Watching for file changes with StatReloader
/src/quickstart/settings.py changed, reloading.
Watching for file changes with StatReloader
Watching for file changes with StatReloader
Internal Server Error: /hello/
Traceback (most recent call last):
  File "/usr/local/lib/python3.6/dist-packages/django/core/handlers/exception.py", line 34, in inner
    response = get_response(request)
  File "/usr/local/lib/python3.6/dist-packages/django/core/handlers/base.py", line 115, in _get_response
    response = self.process_exception_by_middleware(e, request)
  File "/usr/local/lib/python3.6/dist-packages/django/core/handlers/base.py", line 113, in _get_response
    response = wrapped_callback(request, *callback_args, **callback_kwargs)
  File "/src/video/views.py", line 5, in hello
    6 / 0
ZeroDivisionError: division by zero
"GET /hello/ HTTP/1.0" 500 27
/src/video/views.py changed, reloading.
Watching for file changes with StatReloader
"GET /hello/ HTTP/1.0" 200 11
/src/quickstart/settings.py changed, reloading.
Not Found: /
Not Found: /favicon.ico
Not Found: /
Internal Server Error: /hello/
Traceback (most recent call last):
  File "/usr/local/lib/python3.6/dist-packages/django/core/handlers/exception.py", line 34, in inner
    response = get_response(request)
  File "/usr/local/lib/python3.6/dist-packages/django/core/handlers/base.py", line 115, in _get_response
    response = self.process_exception_by_middleware(e, request)
  File "/usr/local/lib/python3.6/dist-packages/django/core/handlers/base.py", line 113, in _get_response
    response = wrapped_callback(request, *callback_args, **callback_kwargs)
  File "/src/video/views.py", line 7, in hello
    6/0
ZeroDivisionError: division by zero
Internal Server Error: /hello/
Traceback (most recent call last):
  File "/usr/local/lib/python3.6/dist-packages/django/core/handlers/exception.py", line 34, in inner
    response = get_response(request)
  File "/usr/local/lib/python3.6/dist-packages/django/core/handlers/base.py", line 115, in _get_response
    response = self.process_exception_by_middleware(e, request)
  File "/usr/local/lib/python3.6/dist-packages/django/core/handlers/base.py", line 113, in _get_response
    response = wrapped_callback(request, *callback_args, **callback_kwargs)
  File "/src/video/views.py", line 7, in hello
    return render(request, "index.html")
ZeroDivisionError: division by zero
Not Found: /
Not Found: /favicon.ico
Internal Server Error: /hello/
Traceback (most recent call last):
  File "/usr/local/lib/python3.6/dist-packages/django/core/handlers/exception.py", line 34, in inner
    response = get_response(request)
  File "/usr/local/lib/python3.6/dist-packages/django/core/handlers/base.py", line 115, in _get_response
    response = self.process_exception_by_middleware(e, request)
  File "/usr/local/lib/python3.6/dist-packages/django/core/handlers/base.py", line 113, in _get_response
    response = wrapped_callback(request, *callback_args, **callback_kwargs)
  File "/src/video/views.py", line 9, in hello
    return render(request, "index.html", response)
  File "/usr/local/lib/python3.6/dist-packages/django/shortcuts.py", line 36, in render
    content = loader.render_to_string(template_name, context, request, using=using)
  File "/usr/local/lib/python3.6/dist-packages/django/template/loader.py", line 61, in render_to_string
    template = get_template(template_name, using=using)
  File "/usr/local/lib/python3.6/dist-packages/django/template/loader.py", line 15, in get_template
    return engine.get_template(template_name)
  File "/usr/local/lib/python3.6/dist-packages/django/template/backends/django.py", line 34, in get_template
    return Template(self.engine.get_template(template_name), self)
  File "/usr/local/lib/python3.6/dist-packages/django/template/engine.py", line 143, in get_template
    template, origin = self.find_template(template_name)
  File "/usr/local/lib/python3.6/dist-packages/django/template/engine.py", line 125, in find_template
    template = loader.get_template(name, skip=skip)
  File "/usr/local/lib/python3.6/dist-packages/django/template/loaders/cached.py", line 54, in get_template
    template = super().get_template(template_name, skip)
  File "/usr/local/lib/python3.6/dist-packages/django/template/loaders/base.py", line 30, in get_template
    contents, origin, origin.template_name, self.engine,
  File "/usr/local/lib/python3.6/dist-packages/django/template/base.py", line 156, in __init__
    self.nodelist = self.compile_nodelist()
  File "/usr/local/lib/python3.6/dist-packages/django/template/base.py", line 194, in compile_nodelist
    return parser.parse()
  File "/usr/local/lib/python3.6/dist-packages/django/template/base.py", line 478, in parse
    raise self.error(token, e)
  File "/usr/local/lib/python3.6/dist-packages/django/template/base.py", line 476, in parse
    compiled_result = compile_func(self, token)
  File "/usr/local/lib/python3.6/dist-packages/django/template/defaulttags.py", line 811, in do_for
    nodelist_loop = parser.parse(('empty', 'endfor',))
  File "/usr/local/lib/python3.6/dist-packages/django/template/base.py", line 449, in parse
    raise self.error(token, e)
  File "/usr/local/lib/python3.6/dist-packages/django/template/base.py", line 447, in parse
    filter_expression = self.compile_filter(token.contents)
  File "/usr/local/lib/python3.6/dist-packages/django/template/base.py", line 563, in compile_filter
    return FilterExpression(token, self)
  File "/usr/local/lib/python3.6/dist-packages/django/template/base.py", line 663, in __init__
    "from '%s'" % (token[upto:], token))
django.template.exceptions.TemplateSyntaxError: Could not parse the remainder: '|' from 'video.comment_set.all|'
Internal Server Error: /hello/
Traceback (most recent call last):
  File "/usr/local/lib/python3.6/dist-packages/django/template/base.py", line 829, in _resolve_lookup
    current = current[bit]
TypeError: 'MyVideo' object is not subscriptable

During handling of the above exception, another exception occurred:

Traceback (most recent call last):
  File "/usr/local/lib/python3.6/dist-packages/django/core/handlers/exception.py", line 34, in inner
    response = get_response(request)
  File "/usr/local/lib/python3.6/dist-packages/django/core/handlers/base.py", line 115, in _get_response
    response = self.process_exception_by_middleware(e, request)
  File "/usr/local/lib/python3.6/dist-packages/django/core/handlers/base.py", line 113, in _get_response
    response = wrapped_callback(request, *callback_args, **callback_kwargs)
  File "/src/video/views.py", line 9, in hello
    return render(request, "index.html", response)
  File "/usr/local/lib/python3.6/dist-packages/django/shortcuts.py", line 36, in render
    content = loader.render_to_string(template_name, context, request, using=using)
  File "/usr/local/lib/python3.6/dist-packages/django/template/loader.py", line 62, in render_to_string
    return template.render(context, request)
  File "/usr/local/lib/python3.6/dist-packages/django/template/backends/django.py", line 61, in render
    return self.template.render(context)
  File "/usr/local/lib/python3.6/dist-packages/django/template/base.py", line 171, in render
    return self._render(context)
  File "/usr/local/lib/python3.6/dist-packages/django/template/base.py", line 163, in _render
    return self.nodelist.render(context)
  File "/usr/local/lib/python3.6/dist-packages/django/template/base.py", line 937, in render
    bit = node.render_annotated(context)
  File "/usr/local/lib/python3.6/dist-packages/django/template/base.py", line 904, in render_annotated
    return self.render(context)
  File "/usr/local/lib/python3.6/dist-packages/django/template/defaulttags.py", line 209, in render
    nodelist.append(node.render_annotated(context))
  File "/usr/local/lib/python3.6/dist-packages/django/template/base.py", line 904, in render_annotated
    return self.render(context)
  File "/usr/local/lib/python3.6/dist-packages/django/template/base.py", line 987, in render
    output = self.filter_expression.resolve(context)
  File "/usr/local/lib/python3.6/dist-packages/django/template/base.py", line 671, in resolve
    obj = self.var.resolve(context)
  File "/usr/local/lib/python3.6/dist-packages/django/template/base.py", line 796, in resolve
    value = self._resolve_lookup(context)
  File "/usr/local/lib/python3.6/dist-packages/django/template/base.py", line 837, in _resolve_lookup
    current = getattr(current, bit)
  File "/src/video/models.py", line 28, in long_post
    return dt.now() - self.date.date()
TypeError: unsupported operand type(s) for -: 'datetime.datetime' and 'datetime.date'
Internal Server Error: /hello/
Traceback (most recent call last):
  File "/usr/local/lib/python3.6/dist-packages/django/contrib/sessions/backends/base.py", line 189, in _get_session
    return self._session_cache
AttributeError: 'SessionStore' object has no attribute '_session_cache'

During handling of the above exception, another exception occurred:

Traceback (most recent call last):
  File "/usr/local/lib/python3.6/dist-packages/django/db/backends/utils.py", line 84, in _execute
    return self.cursor.execute(sql, params)
psycopg2.errors.UndefinedTable: relation "django_session" does not exist
LINE 1: ...ession_data", "django_session"."expire_date" FROM "django_se...
                                                             ^


The above exception was the direct cause of the following exception:

Traceback (most recent call last):
  File "/usr/local/lib/python3.6/dist-packages/django/core/handlers/exception.py", line 34, in inner
    response = get_response(request)
  File "/usr/local/lib/python3.6/dist-packages/django/core/handlers/base.py", line 115, in _get_response
    response = self.process_exception_by_middleware(e, request)
  File "/usr/local/lib/python3.6/dist-packages/django/core/handlers/base.py", line 113, in _get_response
    response = wrapped_callback(request, *callback_args, **callback_kwargs)
  File "/usr/local/lib/python3.6/dist-packages/django/views/decorators/csrf.py", line 54, in wrapped_view
    return view_func(*args, **kwargs)
  File "/usr/local/lib/python3.6/dist-packages/django/views/generic/base.py", line 71, in view
    return self.dispatch(request, *args, **kwargs)
  File "/usr/local/lib/python3.6/dist-packages/rest_framework/views.py", line 505, in dispatch
    response = self.handle_exception(exc)
  File "/usr/local/lib/python3.6/dist-packages/rest_framework/views.py", line 465, in handle_exception
    self.raise_uncaught_exception(exc)
  File "/usr/local/lib/python3.6/dist-packages/rest_framework/views.py", line 476, in raise_uncaught_exception
    raise exc
  File "/usr/local/lib/python3.6/dist-packages/rest_framework/views.py", line 493, in dispatch
    self.initial(request, *args, **kwargs)
  File "/usr/local/lib/python3.6/dist-packages/rest_framework/views.py", line 410, in initial
    self.perform_authentication(request)
  File "/usr/local/lib/python3.6/dist-packages/rest_framework/views.py", line 324, in perform_authentication
    request.user
  File "/usr/local/lib/python3.6/dist-packages/rest_framework/request.py", line 220, in user
    self._authenticate()
  File "/usr/local/lib/python3.6/dist-packages/rest_framework/request.py", line 373, in _authenticate
    user_auth_tuple = authenticator.authenticate(self)
  File "/usr/local/lib/python3.6/dist-packages/rest_framework/authentication.py", line 123, in authenticate
    if not user or not user.is_active:
  File "/usr/local/lib/python3.6/dist-packages/django/utils/functional.py", line 256, in inner
    self._setup()
  File "/usr/local/lib/python3.6/dist-packages/django/utils/functional.py", line 392, in _setup
    self._wrapped = self._setupfunc()
  File "/usr/local/lib/python3.6/dist-packages/django/contrib/auth/middleware.py", line 24, in <lambda>
    request.user = SimpleLazyObject(lambda: get_user(request))
  File "/usr/local/lib/python3.6/dist-packages/django/contrib/auth/middleware.py", line 12, in get_user
    request._cached_user = auth.get_user(request)
  File "/usr/local/lib/python3.6/dist-packages/django/contrib/auth/__init__.py", line 182, in get_user
    user_id = _get_user_session_key(request)
  File "/usr/local/lib/python3.6/dist-packages/django/contrib/auth/__init__.py", line 59, in _get_user_session_key
    return get_user_model()._meta.pk.to_python(request.session[SESSION_KEY])
  File "/usr/local/lib/python3.6/dist-packages/django/contrib/sessions/backends/base.py", line 54, in __getitem__
    return self._session[key]
  File "/usr/local/lib/python3.6/dist-packages/django/contrib/sessions/backends/base.py", line 194, in _get_session
    self._session_cache = self.load()
  File "/usr/local/lib/python3.6/dist-packages/django/contrib/sessions/backends/db.py", line 43, in load
    s = self._get_session_from_db()
  File "/usr/local/lib/python3.6/dist-packages/django/contrib/sessions/backends/db.py", line 34, in _get_session_from_db
    expire_date__gt=timezone.now()
  File "/usr/local/lib/python3.6/dist-packages/django/db/models/manager.py", line 82, in manager_method
    return getattr(self.get_queryset(), name)(*args, **kwargs)
  File "/usr/local/lib/python3.6/dist-packages/django/db/models/query.py", line 402, in get
    num = len(clone)
  File "/usr/local/lib/python3.6/dist-packages/django/db/models/query.py", line 256, in __len__
    self._fetch_all()
  File "/usr/local/lib/python3.6/dist-packages/django/db/models/query.py", line 1242, in _fetch_all
    self._result_cache = list(self._iterable_class(self))
  File "/usr/local/lib/python3.6/dist-packages/django/db/models/query.py", line 55, in __iter__
    results = compiler.execute_sql(chunked_fetch=self.chunked_fetch, chunk_size=self.chunk_size)
  File "/usr/local/lib/python3.6/dist-packages/django/db/models/sql/compiler.py", line 1100, in execute_sql
    cursor.execute(sql, params)
  File "/usr/local/lib/python3.6/dist-packages/django/db/backends/utils.py", line 67, in execute
    return self._execute_with_wrappers(sql, params, many=False, executor=self._execute)
  File "/usr/local/lib/python3.6/dist-packages/django/db/backends/utils.py", line 76, in _execute_with_wrappers
    return executor(sql, params, many, context)
  File "/usr/local/lib/python3.6/dist-packages/django/db/backends/utils.py", line 84, in _execute
    return self.cursor.execute(sql, params)
  File "/usr/local/lib/python3.6/dist-packages/django/db/utils.py", line 89, in __exit__
    raise dj_exc_value.with_traceback(traceback) from exc_value
  File "/usr/local/lib/python3.6/dist-packages/django/db/backends/utils.py", line 84, in _execute
    return self.cursor.execute(sql, params)
django.db.utils.ProgrammingError: relation "django_session" does not exist
LINE 1: ...ession_data", "django_session"."expire_date" FROM "django_se...
                                                             ^

Not Found: /favicon.ico
Not Found: /
Not Found: /rtfghf/
Not Found: /rtfghf/
Not Found: /rtfghf/
Not Found: /rtfghf/
Not Found: /rtfghf/
Not Found: /rtfghf/
Not Found: /rtfghf/
Not Found: /rtfghf/
Not Found: /rtfghf/
Not Found: /rtfghf/
Not Found: /rtfghf/
Not Found: /rtfghf/
Not Found: /rtfghf/
Not Found: /rtfghf/
Not Found: /rtfghf/
Not Found: /
Not Found: /favicon.ico
Internal Server Error: /hello/
Traceback (most recent call last):
  File "/usr/local/lib/python3.6/dist-packages/django/contrib/sessions/backends/base.py", line 189, in _get_session
    return self._session_cache
AttributeError: 'SessionStore' object has no attribute '_session_cache'

During handling of the above exception, another exception occurred:

Traceback (most recent call last):
  File "/usr/local/lib/python3.6/dist-packages/django/db/backends/utils.py", line 84, in _execute
    return self.cursor.execute(sql, params)
psycopg2.errors.UndefinedTable: relation "django_session" does not exist
LINE 1: ...ession_data", "django_session"."expire_date" FROM "django_se...
                                                             ^


The above exception was the direct cause of the following exception:

Traceback (most recent call last):
  File "/usr/local/lib/python3.6/dist-packages/django/core/handlers/exception.py", line 34, in inner
    response = get_response(request)
  File "/usr/local/lib/python3.6/dist-packages/django/core/handlers/base.py", line 115, in _get_response
    response = self.process_exception_by_middleware(e, request)
  File "/usr/local/lib/python3.6/dist-packages/django/core/handlers/base.py", line 113, in _get_response
    response = wrapped_callback(request, *callback_args, **callback_kwargs)
  File "/usr/local/lib/python3.6/dist-packages/django/views/decorators/csrf.py", line 54, in wrapped_view
    return view_func(*args, **kwargs)
  File "/usr/local/lib/python3.6/dist-packages/django/views/generic/base.py", line 71, in view
    return self.dispatch(request, *args, **kwargs)
  File "/usr/local/lib/python3.6/dist-packages/rest_framework/views.py", line 505, in dispatch
    response = self.handle_exception(exc)
  File "/usr/local/lib/python3.6/dist-packages/rest_framework/views.py", line 465, in handle_exception
    self.raise_uncaught_exception(exc)
  File "/usr/local/lib/python3.6/dist-packages/rest_framework/views.py", line 476, in raise_uncaught_exception
    raise exc
  File "/usr/local/lib/python3.6/dist-packages/rest_framework/views.py", line 493, in dispatch
    self.initial(request, *args, **kwargs)
  File "/usr/local/lib/python3.6/dist-packages/rest_framework/views.py", line 410, in initial
    self.perform_authentication(request)
  File "/usr/local/lib/python3.6/dist-packages/rest_framework/views.py", line 324, in perform_authentication
    request.user
  File "/usr/local/lib/python3.6/dist-packages/rest_framework/request.py", line 220, in user
    self._authenticate()
  File "/usr/local/lib/python3.6/dist-packages/rest_framework/request.py", line 373, in _authenticate
    user_auth_tuple = authenticator.authenticate(self)
  File "/usr/local/lib/python3.6/dist-packages/rest_framework/authentication.py", line 123, in authenticate
    if not user or not user.is_active:
  File "/usr/local/lib/python3.6/dist-packages/django/utils/functional.py", line 256, in inner
    self._setup()
  File "/usr/local/lib/python3.6/dist-packages/django/utils/functional.py", line 392, in _setup
    self._wrapped = self._setupfunc()
  File "/usr/local/lib/python3.6/dist-packages/django/contrib/auth/middleware.py", line 24, in <lambda>
    request.user = SimpleLazyObject(lambda: get_user(request))
  File "/usr/local/lib/python3.6/dist-packages/django/contrib/auth/middleware.py", line 12, in get_user
    request._cached_user = auth.get_user(request)
  File "/usr/local/lib/python3.6/dist-packages/django/contrib/auth/__init__.py", line 182, in get_user
    user_id = _get_user_session_key(request)
  File "/usr/local/lib/python3.6/dist-packages/django/contrib/auth/__init__.py", line 59, in _get_user_session_key
    return get_user_model()._meta.pk.to_python(request.session[SESSION_KEY])
  File "/usr/local/lib/python3.6/dist-packages/django/contrib/sessions/backends/base.py", line 54, in __getitem__
    return self._session[key]
  File "/usr/local/lib/python3.6/dist-packages/django/contrib/sessions/backends/base.py", line 194, in _get_session
    self._session_cache = self.load()
  File "/usr/local/lib/python3.6/dist-packages/django/contrib/sessions/backends/db.py", line 43, in load
    s = self._get_session_from_db()
  File "/usr/local/lib/python3.6/dist-packages/django/contrib/sessions/backends/db.py", line 34, in _get_session_from_db
    expire_date__gt=timezone.now()
  File "/usr/local/lib/python3.6/dist-packages/django/db/models/manager.py", line 82, in manager_method
    return getattr(self.get_queryset(), name)(*args, **kwargs)
  File "/usr/local/lib/python3.6/dist-packages/django/db/models/query.py", line 402, in get
    num = len(clone)
  File "/usr/local/lib/python3.6/dist-packages/django/db/models/query.py", line 256, in __len__
    self._fetch_all()
  File "/usr/local/lib/python3.6/dist-packages/django/db/models/query.py", line 1242, in _fetch_all
    self._result_cache = list(self._iterable_class(self))
  File "/usr/local/lib/python3.6/dist-packages/django/db/models/query.py", line 55, in __iter__
    results = compiler.execute_sql(chunked_fetch=self.chunked_fetch, chunk_size=self.chunk_size)
  File "/usr/local/lib/python3.6/dist-packages/django/db/models/sql/compiler.py", line 1100, in execute_sql
    cursor.execute(sql, params)
  File "/usr/local/lib/python3.6/dist-packages/django/db/backends/utils.py", line 67, in execute
    return self._execute_with_wrappers(sql, params, many=False, executor=self._execute)
  File "/usr/local/lib/python3.6/dist-packages/django/db/backends/utils.py", line 76, in _execute_with_wrappers
    return executor(sql, params, many, context)
  File "/usr/local/lib/python3.6/dist-packages/django/db/backends/utils.py", line 84, in _execute
    return self.cursor.execute(sql, params)
  File "/usr/local/lib/python3.6/dist-packages/django/db/utils.py", line 89, in __exit__
    raise dj_exc_value.with_traceback(traceback) from exc_value
  File "/usr/local/lib/python3.6/dist-packages/django/db/backends/utils.py", line 84, in _execute
    return self.cursor.execute(sql, params)
django.db.utils.ProgrammingError: relation "django_session" does not exist
LINE 1: ...ession_data", "django_session"."expire_date" FROM "django_se...
                                                             ^

Not Found: /video.slug/
Not Found: /video.slug/
Not Found: /oxxxymiron-gorod-pod-podoshvoj-2015/
Not Found: /hello/oxxxymiron-gorod-pod-podoshvoj-2015/
Not Found: /hello/oxxxymiron-gorod-pod-podoshvoj-2015/
Not Found: /hello/oxxxymiron-gorod-pod-podoshvoj-2015/
Not Found: /rtfghf/
Not Found: /rtfghf/
Not Found: /rtfghf/
Not Found: /rtfghf/
Not Found: /static/admin/css/base.css
Not Found: /static/admin/css/login.css
Not Found: /static/admin/css/responsive.css
Not Found: /favicon.ico
Not Found: /rtfghf/
Not Found: /static/admin/css/base.css
Not Found: /static/admin/css/login.css
Not Found: /static/admin/css/responsive.css
Not Found: /favicon.ico
Not Found: /static/admin/css/base.css
Not Found: /static/admin/css/responsive.css
Not Found: /static/admin/css/dashboard.css
Not Found: /rtfghf/
Not Found: /static/admin/css/base.css
Not Found: /static/admin/css/login.css
Not Found: /static/admin/css/responsive.css
Not Found: /favicon.ico
Not Found: /static/admin/css/base.css
Not Found: /static/admin/css/responsive.css
Not Found: /static/admin/css/dashboard.css
Not Found: /rtfghf/
Not Found: /static/admin/css/base.css
Not Found: /static/admin/css/login.css
Not Found: /static/admin/css/responsive.css
Not Found: /favicon.ico
Not Found: /static/admin/css/base.css
Not Found: /static/admin/css/responsive.css
Not Found: /static/admin/css/dashboard.css
Not Found: /rtfghf/
Not Found: /static/admin/css/base.css
Not Found: /static/admin/css/login.css
Not Found: /static/admin/css/responsive.css
Not Found: /favicon.ico
Not Found: /static/admin/css/base.css
Not Found: /static/admin/css/responsive.css
Not Found: /static/admin/css/dashboard.css
Internal Server Error: /hello/test_slug/
Traceback (most recent call last):
  File "/usr/local/lib/python3.6/dist-packages/django/core/handlers/exception.py", line 34, in inner
    response = get_response(request)
  File "/usr/local/lib/python3.6/dist-packages/django/core/handlers/base.py", line 115, in _get_response
    response = self.process_exception_by_middleware(e, request)
  File "/usr/local/lib/python3.6/dist-packages/django/core/handlers/base.py", line 113, in _get_response
    response = wrapped_callback(request, *callback_args, **callback_kwargs)
  File "/src/video/views.py", line 33, in show_one
    one_video = MyVideo.objects.get(slug=slug)
  File "/usr/local/lib/python3.6/dist-packages/django/db/models/manager.py", line 82, in manager_method
    return getattr(self.get_queryset(), name)(*args, **kwargs)
  File "/usr/local/lib/python3.6/dist-packages/django/db/models/query.py", line 408, in get
    self.model._meta.object_name
video.models.MyVideo.DoesNotExist: MyVideo matching query does not exist.
Not Found: /favicon.ico
Not Found: /rtfghf/
Not Found: /static/admin/css/base.css
Not Found: /static/admin/css/login.css
Not Found: /static/admin/css/responsive.css
Not Found: /favicon.ico
Not Found: /static/admin/css/base.css
Not Found: /static/admin/css/responsive.css
Not Found: /static/admin/css/dashboard.css
Not Found: /rtfghf/
Not Found: /static/admin/css/base.css
Not Found: /static/admin/css/login.css
Not Found: /static/admin/css/responsive.css
Not Found: /favicon.ico
Not Found: /static/admin/css/base.css
Not Found: /static/admin/css/responsive.css
Not Found: /static/admin/css/dashboard.css
Not Found: /rtfghf/
Not Found: /static/admin/css/base.css
Not Found: /static/admin/css/login.css
Not Found: /static/admin/css/responsive.css
Not Found: /favicon.ico
Not Found: /static/admin/css/base.css
Not Found: /static/admin/css/responsive.css
Not Found: /static/admin/css/dashboard.css
Not Found: /rtfghf/
Not Found: /static/admin/css/base.css
Not Found: /static/admin/css/login.css
Not Found: /static/admin/css/responsive.css
Not Found: /favicon.ico
Not Found: /static/admin/css/base.css
Not Found: /static/admin/css/responsive.css
Not Found: /static/admin/css/dashboard.css
Not Found: /rtfghf/
Not Found: /rtfghf/
Not Found: /rtfghf/
Not Found: /rtfghf/
Not Found: /static/admin/css/base.css
Not Found: /static/admin/css/login.css
Not Found: /static/admin/css/responsive.css
Not Found: /favicon.ico
Internal Server Error: /admin/login/
Traceback (most recent call last):
  File "/usr/local/lib/python3.6/dist-packages/django/db/backends/utils.py", line 84, in _execute
    return self.cursor.execute(sql, params)
psycopg2.errors.UndefinedTable: relation "auth_user" does not exist
LINE 1: ...user"."is_active", "auth_user"."date_joined" FROM "auth_user...
                                                             ^


The above exception was the direct cause of the following exception:

Traceback (most recent call last):
  File "/usr/local/lib/python3.6/dist-packages/django/core/handlers/exception.py", line 34, in inner
    response = get_response(request)
  File "/usr/local/lib/python3.6/dist-packages/django/core/handlers/base.py", line 115, in _get_response
    response = self.process_exception_by_middleware(e, request)
  File "/usr/local/lib/python3.6/dist-packages/django/core/handlers/base.py", line 113, in _get_response
    response = wrapped_callback(request, *callback_args, **callback_kwargs)
  File "/usr/local/lib/python3.6/dist-packages/django/views/decorators/cache.py", line 44, in _wrapped_view_func
    response = view_func(request, *args, **kwargs)
  File "/usr/local/lib/python3.6/dist-packages/django/contrib/admin/sites.py", line 399, in login
    return LoginView.as_view(**defaults)(request)
  File "/usr/local/lib/python3.6/dist-packages/django/views/generic/base.py", line 71, in view
    return self.dispatch(request, *args, **kwargs)
  File "/usr/local/lib/python3.6/dist-packages/django/utils/decorators.py", line 45, in _wrapper
    return bound_method(*args, **kwargs)
  File "/usr/local/lib/python3.6/dist-packages/django/views/decorators/debug.py", line 76, in sensitive_post_parameters_wrapper
    return view(request, *args, **kwargs)
  File "/usr/local/lib/python3.6/dist-packages/django/utils/decorators.py", line 45, in _wrapper
    return bound_method(*args, **kwargs)
  File "/usr/local/lib/python3.6/dist-packages/django/utils/decorators.py", line 142, in _wrapped_view
    response = view_func(request, *args, **kwargs)
  File "/usr/local/lib/python3.6/dist-packages/django/utils/decorators.py", line 45, in _wrapper
    return bound_method(*args, **kwargs)
  File "/usr/local/lib/python3.6/dist-packages/django/views/decorators/cache.py", line 44, in _wrapped_view_func
    response = view_func(request, *args, **kwargs)
  File "/usr/local/lib/python3.6/dist-packages/django/contrib/auth/views.py", line 61, in dispatch
    return super().dispatch(request, *args, **kwargs)
  File "/usr/local/lib/python3.6/dist-packages/django/views/generic/base.py", line 97, in dispatch
    return handler(request, *args, **kwargs)
  File "/usr/local/lib/python3.6/dist-packages/django/views/generic/edit.py", line 141, in post
    if form.is_valid():
  File "/usr/local/lib/python3.6/dist-packages/django/forms/forms.py", line 185, in is_valid
    return self.is_bound and not self.errors
  File "/usr/local/lib/python3.6/dist-packages/django/forms/forms.py", line 180, in errors
    self.full_clean()
  File "/usr/local/lib/python3.6/dist-packages/django/forms/forms.py", line 382, in full_clean
    self._clean_form()
  File "/usr/local/lib/python3.6/dist-packages/django/forms/forms.py", line 409, in _clean_form
    cleaned_data = self.clean()
  File "/usr/local/lib/python3.6/dist-packages/django/contrib/auth/forms.py", line 196, in clean
    self.user_cache = authenticate(self.request, username=username, password=password)
  File "/usr/local/lib/python3.6/dist-packages/django/contrib/auth/__init__.py", line 73, in authenticate
    user = backend.authenticate(request, **credentials)
  File "/usr/local/lib/python3.6/dist-packages/django/contrib/auth/backends.py", line 20, in authenticate
    user = UserModel._default_manager.get_by_natural_key(username)
  File "/usr/local/lib/python3.6/dist-packages/django/contrib/auth/base_user.py", line 44, in get_by_natural_key
    return self.get(**{self.model.USERNAME_FIELD: username})
  File "/usr/local/lib/python3.6/dist-packages/django/db/models/manager.py", line 82, in manager_method
    return getattr(self.get_queryset(), name)(*args, **kwargs)
  File "/usr/local/lib/python3.6/dist-packages/django/db/models/query.py", line 402, in get
    num = len(clone)
  File "/usr/local/lib/python3.6/dist-packages/django/db/models/query.py", line 256, in __len__
    self._fetch_all()
  File "/usr/local/lib/python3.6/dist-packages/django/db/models/query.py", line 1242, in _fetch_all
    self._result_cache = list(self._iterable_class(self))
  File "/usr/local/lib/python3.6/dist-packages/django/db/models/query.py", line 55, in __iter__
    results = compiler.execute_sql(chunked_fetch=self.chunked_fetch, chunk_size=self.chunk_size)
  File "/usr/local/lib/python3.6/dist-packages/django/db/models/sql/compiler.py", line 1100, in execute_sql
    cursor.execute(sql, params)
  File "/usr/local/lib/python3.6/dist-packages/django/db/backends/utils.py", line 67, in execute
    return self._execute_with_wrappers(sql, params, many=False, executor=self._execute)
  File "/usr/local/lib/python3.6/dist-packages/django/db/backends/utils.py", line 76, in _execute_with_wrappers
    return executor(sql, params, many, context)
  File "/usr/local/lib/python3.6/dist-packages/django/db/backends/utils.py", line 84, in _execute
    return self.cursor.execute(sql, params)
  File "/usr/local/lib/python3.6/dist-packages/django/db/utils.py", line 89, in __exit__
    raise dj_exc_value.with_traceback(traceback) from exc_value
  File "/usr/local/lib/python3.6/dist-packages/django/db/backends/utils.py", line 84, in _execute
    return self.cursor.execute(sql, params)
django.db.utils.ProgrammingError: relation "auth_user" does not exist
LINE 1: ...user"."is_active", "auth_user"."date_joined" FROM "auth_user...
                                                             ^

Not Found: /rtfghf/
Not Found: /static/admin/css/base.css
Not Found: /static/admin/css/login.css
Not Found: /static/admin/css/responsive.css
Not Found: /favicon.ico
Internal Server Error: /admin/login/
Traceback (most recent call last):
  File "/usr/local/lib/python3.6/dist-packages/django/db/backends/utils.py", line 84, in _execute
    return self.cursor.execute(sql, params)
psycopg2.errors.UndefinedTable: relation "auth_user" does not exist
LINE 1: ...user"."is_active", "auth_user"."date_joined" FROM "auth_user...
                                                             ^


The above exception was the direct cause of the following exception:

Traceback (most recent call last):
  File "/usr/local/lib/python3.6/dist-packages/django/core/handlers/exception.py", line 34, in inner
    response = get_response(request)
  File "/usr/local/lib/python3.6/dist-packages/django/core/handlers/base.py", line 115, in _get_response
    response = self.process_exception_by_middleware(e, request)
  File "/usr/local/lib/python3.6/dist-packages/django/core/handlers/base.py", line 113, in _get_response
    response = wrapped_callback(request, *callback_args, **callback_kwargs)
  File "/usr/local/lib/python3.6/dist-packages/django/views/decorators/cache.py", line 44, in _wrapped_view_func
    response = view_func(request, *args, **kwargs)
  File "/usr/local/lib/python3.6/dist-packages/django/contrib/admin/sites.py", line 399, in login
    return LoginView.as_view(**defaults)(request)
  File "/usr/local/lib/python3.6/dist-packages/django/views/generic/base.py", line 71, in view
    return self.dispatch(request, *args, **kwargs)
  File "/usr/local/lib/python3.6/dist-packages/django/utils/decorators.py", line 45, in _wrapper
    return bound_method(*args, **kwargs)
  File "/usr/local/lib/python3.6/dist-packages/django/views/decorators/debug.py", line 76, in sensitive_post_parameters_wrapper
    return view(request, *args, **kwargs)
  File "/usr/local/lib/python3.6/dist-packages/django/utils/decorators.py", line 45, in _wrapper
    return bound_method(*args, **kwargs)
  File "/usr/local/lib/python3.6/dist-packages/django/utils/decorators.py", line 142, in _wrapped_view
    response = view_func(request, *args, **kwargs)
  File "/usr/local/lib/python3.6/dist-packages/django/utils/decorators.py", line 45, in _wrapper
    return bound_method(*args, **kwargs)
  File "/usr/local/lib/python3.6/dist-packages/django/views/decorators/cache.py", line 44, in _wrapped_view_func
    response = view_func(request, *args, **kwargs)
  File "/usr/local/lib/python3.6/dist-packages/django/contrib/auth/views.py", line 61, in dispatch
    return super().dispatch(request, *args, **kwargs)
  File "/usr/local/lib/python3.6/dist-packages/django/views/generic/base.py", line 97, in dispatch
    return handler(request, *args, **kwargs)
  File "/usr/local/lib/python3.6/dist-packages/django/views/generic/edit.py", line 141, in post
    if form.is_valid():
  File "/usr/local/lib/python3.6/dist-packages/django/forms/forms.py", line 185, in is_valid
    return self.is_bound and not self.errors
  File "/usr/local/lib/python3.6/dist-packages/django/forms/forms.py", line 180, in errors
    self.full_clean()
  File "/usr/local/lib/python3.6/dist-packages/django/forms/forms.py", line 382, in full_clean
    self._clean_form()
  File "/usr/local/lib/python3.6/dist-packages/django/forms/forms.py", line 409, in _clean_form
    cleaned_data = self.clean()
  File "/usr/local/lib/python3.6/dist-packages/django/contrib/auth/forms.py", line 196, in clean
    self.user_cache = authenticate(self.request, username=username, password=password)
  File "/usr/local/lib/python3.6/dist-packages/django/contrib/auth/__init__.py", line 73, in authenticate
    user = backend.authenticate(request, **credentials)
  File "/usr/local/lib/python3.6/dist-packages/django/contrib/auth/backends.py", line 20, in authenticate
    user = UserModel._default_manager.get_by_natural_key(username)
  File "/usr/local/lib/python3.6/dist-packages/django/contrib/auth/base_user.py", line 44, in get_by_natural_key
    return self.get(**{self.model.USERNAME_FIELD: username})
  File "/usr/local/lib/python3.6/dist-packages/django/db/models/manager.py", line 82, in manager_method
    return getattr(self.get_queryset(), name)(*args, **kwargs)
  File "/usr/local/lib/python3.6/dist-packages/django/db/models/query.py", line 402, in get
    num = len(clone)
  File "/usr/local/lib/python3.6/dist-packages/django/db/models/query.py", line 256, in __len__
    self._fetch_all()
  File "/usr/local/lib/python3.6/dist-packages/django/db/models/query.py", line 1242, in _fetch_all
    self._result_cache = list(self._iterable_class(self))
  File "/usr/local/lib/python3.6/dist-packages/django/db/models/query.py", line 55, in __iter__
    results = compiler.execute_sql(chunked_fetch=self.chunked_fetch, chunk_size=self.chunk_size)
  File "/usr/local/lib/python3.6/dist-packages/django/db/models/sql/compiler.py", line 1100, in execute_sql
    cursor.execute(sql, params)
  File "/usr/local/lib/python3.6/dist-packages/django/db/backends/utils.py", line 67, in execute
    return self._execute_with_wrappers(sql, params, many=False, executor=self._execute)
  File "/usr/local/lib/python3.6/dist-packages/django/db/backends/utils.py", line 76, in _execute_with_wrappers
    return executor(sql, params, many, context)
  File "/usr/local/lib/python3.6/dist-packages/django/db/backends/utils.py", line 84, in _execute
    return self.cursor.execute(sql, params)
  File "/usr/local/lib/python3.6/dist-packages/django/db/utils.py", line 89, in __exit__
    raise dj_exc_value.with_traceback(traceback) from exc_value
  File "/usr/local/lib/python3.6/dist-packages/django/db/backends/utils.py", line 84, in _execute
    return self.cursor.execute(sql, params)
django.db.utils.ProgrammingError: relation "auth_user" does not exist
LINE 1: ...user"."is_active", "auth_user"."date_joined" FROM "auth_user...
                                                             ^

Not Found: /rtfghf/
Not Found: /static/admin/css/base.css
Not Found: /static/admin/css/login.css
Not Found: /static/admin/css/responsive.css
Not Found: /favicon.ico
Internal Server Error: /admin/login/
Traceback (most recent call last):
  File "/usr/local/lib/python3.6/dist-packages/django/db/backends/utils.py", line 84, in _execute
    return self.cursor.execute(sql, params)
psycopg2.errors.UndefinedTable: relation "auth_user" does not exist
LINE 1: ...user"."is_active", "auth_user"."date_joined" FROM "auth_user...
                                                             ^


The above exception was the direct cause of the following exception:

Traceback (most recent call last):
  File "/usr/local/lib/python3.6/dist-packages/django/core/handlers/exception.py", line 34, in inner
    response = get_response(request)
  File "/usr/local/lib/python3.6/dist-packages/django/core/handlers/base.py", line 115, in _get_response
    response = self.process_exception_by_middleware(e, request)
  File "/usr/local/lib/python3.6/dist-packages/django/core/handlers/base.py", line 113, in _get_response
    response = wrapped_callback(request, *callback_args, **callback_kwargs)
  File "/usr/local/lib/python3.6/dist-packages/django/views/decorators/cache.py", line 44, in _wrapped_view_func
    response = view_func(request, *args, **kwargs)
  File "/usr/local/lib/python3.6/dist-packages/django/contrib/admin/sites.py", line 399, in login
    return LoginView.as_view(**defaults)(request)
  File "/usr/local/lib/python3.6/dist-packages/django/views/generic/base.py", line 71, in view
    return self.dispatch(request, *args, **kwargs)
  File "/usr/local/lib/python3.6/dist-packages/django/utils/decorators.py", line 45, in _wrapper
    return bound_method(*args, **kwargs)
  File "/usr/local/lib/python3.6/dist-packages/django/views/decorators/debug.py", line 76, in sensitive_post_parameters_wrapper
    return view(request, *args, **kwargs)
  File "/usr/local/lib/python3.6/dist-packages/django/utils/decorators.py", line 45, in _wrapper
    return bound_method(*args, **kwargs)
  File "/usr/local/lib/python3.6/dist-packages/django/utils/decorators.py", line 142, in _wrapped_view
    response = view_func(request, *args, **kwargs)
  File "/usr/local/lib/python3.6/dist-packages/django/utils/decorators.py", line 45, in _wrapper
    return bound_method(*args, **kwargs)
  File "/usr/local/lib/python3.6/dist-packages/django/views/decorators/cache.py", line 44, in _wrapped_view_func
    response = view_func(request, *args, **kwargs)
  File "/usr/local/lib/python3.6/dist-packages/django/contrib/auth/views.py", line 61, in dispatch
    return super().dispatch(request, *args, **kwargs)
  File "/usr/local/lib/python3.6/dist-packages/django/views/generic/base.py", line 97, in dispatch
    return handler(request, *args, **kwargs)
  File "/usr/local/lib/python3.6/dist-packages/django/views/generic/edit.py", line 141, in post
    if form.is_valid():
  File "/usr/local/lib/python3.6/dist-packages/django/forms/forms.py", line 185, in is_valid
    return self.is_bound and not self.errors
  File "/usr/local/lib/python3.6/dist-packages/django/forms/forms.py", line 180, in errors
    self.full_clean()
  File "/usr/local/lib/python3.6/dist-packages/django/forms/forms.py", line 382, in full_clean
    self._clean_form()
  File "/usr/local/lib/python3.6/dist-packages/django/forms/forms.py", line 409, in _clean_form
    cleaned_data = self.clean()
  File "/usr/local/lib/python3.6/dist-packages/django/contrib/auth/forms.py", line 196, in clean
    self.user_cache = authenticate(self.request, username=username, password=password)
  File "/usr/local/lib/python3.6/dist-packages/django/contrib/auth/__init__.py", line 73, in authenticate
    user = backend.authenticate(request, **credentials)
  File "/usr/local/lib/python3.6/dist-packages/django/contrib/auth/backends.py", line 20, in authenticate
    user = UserModel._default_manager.get_by_natural_key(username)
  File "/usr/local/lib/python3.6/dist-packages/django/contrib/auth/base_user.py", line 44, in get_by_natural_key
    return self.get(**{self.model.USERNAME_FIELD: username})
  File "/usr/local/lib/python3.6/dist-packages/django/db/models/manager.py", line 82, in manager_method
    return getattr(self.get_queryset(), name)(*args, **kwargs)
  File "/usr/local/lib/python3.6/dist-packages/django/db/models/query.py", line 402, in get
    num = len(clone)
  File "/usr/local/lib/python3.6/dist-packages/django/db/models/query.py", line 256, in __len__
    self._fetch_all()
  File "/usr/local/lib/python3.6/dist-packages/django/db/models/query.py", line 1242, in _fetch_all
    self._result_cache = list(self._iterable_class(self))
  File "/usr/local/lib/python3.6/dist-packages/django/db/models/query.py", line 55, in __iter__
    results = compiler.execute_sql(chunked_fetch=self.chunked_fetch, chunk_size=self.chunk_size)
  File "/usr/local/lib/python3.6/dist-packages/django/db/models/sql/compiler.py", line 1100, in execute_sql
    cursor.execute(sql, params)
  File "/usr/local/lib/python3.6/dist-packages/django/db/backends/utils.py", line 67, in execute
    return self._execute_with_wrappers(sql, params, many=False, executor=self._execute)
  File "/usr/local/lib/python3.6/dist-packages/django/db/backends/utils.py", line 76, in _execute_with_wrappers
    return executor(sql, params, many, context)
  File "/usr/local/lib/python3.6/dist-packages/django/db/backends/utils.py", line 84, in _execute
    return self.cursor.execute(sql, params)
  File "/usr/local/lib/python3.6/dist-packages/django/db/utils.py", line 89, in __exit__
    raise dj_exc_value.with_traceback(traceback) from exc_value
  File "/usr/local/lib/python3.6/dist-packages/django/db/backends/utils.py", line 84, in _execute
    return self.cursor.execute(sql, params)
django.db.utils.ProgrammingError: relation "auth_user" does not exist
LINE 1: ...user"."is_active", "auth_user"."date_joined" FROM "auth_user...
                                                             ^

Not Found: /
"GET / HTTP/1.1" 404 2258
Not Found: /favicon.ico
"GET /favicon.ico HTTP/1.1" 404 2309
Internal Server Error: /hello/green/
Traceback (most recent call last):
  File "C:\Users\Student\Anaconda3\lib\site-packages\django\core\handlers\exception.py", line 34, in inner
    response = get_response(request)
  File "C:\Users\Student\Anaconda3\lib\site-packages\django\core\handlers\base.py", line 115, in _get_response
    response = self.process_exception_by_middleware(e, request)
  File "C:\Users\Student\Anaconda3\lib\site-packages\django\core\handlers\base.py", line 113, in _get_response
    response = wrapped_callback(request, *callback_args, **callback_kwargs)
  File "D:\django\docker\python2.0\src\video\views.py", line 33, in show_one
    one_video = MyVideo.objects.get(slug=slug)
  File "C:\Users\Student\Anaconda3\lib\site-packages\django\db\models\manager.py", line 82, in manager_method
    return getattr(self.get_queryset(), name)(*args, **kwargs)
  File "C:\Users\Student\Anaconda3\lib\site-packages\django\db\models\query.py", line 408, in get
    self.model._meta.object_name
video.models.MyVideo.DoesNotExist: MyVideo matching query does not exist.
"GET /hello/green/ HTTP/1.1" 500 75579
Internal Server Error: /hello/add_comment_blyt/oxxxymiron-gorod-pod-podoshvoj-2015/
Traceback (most recent call last):
  File "C:\Users\Student\Anaconda3\lib\site-packages\django\core\handlers\exception.py", line 34, in inner
    response = get_response(request)
  File "C:\Users\Student\Anaconda3\lib\site-packages\django\core\handlers\base.py", line 115, in _get_response
    response = self.process_exception_by_middleware(e, request)
  File "C:\Users\Student\Anaconda3\lib\site-packages\django\core\handlers\base.py", line 113, in _get_response
    response = wrapped_callback(request, *callback_args, **callback_kwargs)
  File "D:\django\docker\python2.0\src\video\views.py", line 44, in add_comment
    user=request.user)
  File "C:\Users\Student\Anaconda3\lib\site-packages\django\db\models\manager.py", line 82, in manager_method
    return getattr(self.get_queryset(), name)(*args, **kwargs)
  File "C:\Users\Student\Anaconda3\lib\site-packages\django\db\models\query.py", line 420, in create
    obj = self.model(**kwargs)
  File "C:\Users\Student\Anaconda3\lib\site-packages\django\db\models\base.py", line 483, in __init__
    _setattr(self, field.name, rel_obj)
  File "C:\Users\Student\Anaconda3\lib\site-packages\django\db\models\fields\related_descriptors.py", line 211, in __set__
    self.field.remote_field.model._meta.object_name,
ValueError: Cannot assign "<SimpleLazyObject: <django.contrib.auth.models.AnonymousUser object at 0x00000260470F7B38>>": "Comment.user" must be a "User" instance.
"GET /hello/add_comment_blyt/oxxxymiron-gorod-pod-podoshvoj-2015/?text=hello+drug+blyt HTTP/1.1" 500 87940
Internal Server Error: /hello/
Traceback (most recent call last):
  File "C:\Users\Student\Anaconda3\lib\site-packages\django\core\handlers\exception.py", line 34, in inner
    response = get_response(request)
  File "C:\Users\Student\Anaconda3\lib\site-packages\django\core\handlers\base.py", line 115, in _get_response
    response = self.process_exception_by_middleware(e, request)
  File "C:\Users\Student\Anaconda3\lib\site-packages\django\core\handlers\base.py", line 113, in _get_response
    response = wrapped_callback(request, *callback_args, **callback_kwargs)
  File "C:\Users\Student\Anaconda3\lib\site-packages\django\views\decorators\csrf.py", line 54, in wrapped_view
    return view_func(*args, **kwargs)
  File "C:\Users\Student\Anaconda3\lib\site-packages\django\views\generic\base.py", line 71, in view
    return self.dispatch(request, *args, **kwargs)
  File "C:\Users\Student\Anaconda3\lib\site-packages\rest_framework\views.py", line 505, in dispatch
    response = self.handle_exception(exc)
  File "C:\Users\Student\Anaconda3\lib\site-packages\rest_framework\views.py", line 465, in handle_exception
    self.raise_uncaught_exception(exc)
  File "C:\Users\Student\Anaconda3\lib\site-packages\rest_framework\views.py", line 476, in raise_uncaught_exception
    raise exc
  File "C:\Users\Student\Anaconda3\lib\site-packages\rest_framework\views.py", line 502, in dispatch
    response = handler(request, *args, **kwargs)
  File "C:\Users\Student\Anaconda3\lib\site-packages\rest_framework\decorators.py", line 50, in handler
    return func(*args, **kwargs)
  File "D:\django\docker\python2.0\src\video\views.py", line 27, in hello
    return render(request, "index.html", response)
NameError: name 'response' is not defined
"GET /hello/ HTTP/1.1" 500 100224
Internal Server Error: /hello/
Traceback (most recent call last):
  File "C:\Users\Student\Anaconda3\lib\site-packages\django\core\handlers\exception.py", line 34, in inner
    response = get_response(request)
  File "C:\Users\Student\Anaconda3\lib\site-packages\django\core\handlers\base.py", line 115, in _get_response
    response = self.process_exception_by_middleware(e, request)
  File "C:\Users\Student\Anaconda3\lib\site-packages\django\core\handlers\base.py", line 113, in _get_response
    response = wrapped_callback(request, *callback_args, **callback_kwargs)
  File "C:\Users\Student\Anaconda3\lib\site-packages\django\views\decorators\csrf.py", line 54, in wrapped_view
    return view_func(*args, **kwargs)
  File "C:\Users\Student\Anaconda3\lib\site-packages\django\views\generic\base.py", line 71, in view
    return self.dispatch(request, *args, **kwargs)
  File "C:\Users\Student\Anaconda3\lib\site-packages\rest_framework\views.py", line 505, in dispatch
    response = self.handle_exception(exc)
  File "C:\Users\Student\Anaconda3\lib\site-packages\rest_framework\views.py", line 465, in handle_exception
    self.raise_uncaught_exception(exc)
  File "C:\Users\Student\Anaconda3\lib\site-packages\rest_framework\views.py", line 476, in raise_uncaught_exception
    raise exc
  File "C:\Users\Student\Anaconda3\lib\site-packages\rest_framework\views.py", line 502, in dispatch
    response = handler(request, *args, **kwargs)
  File "C:\Users\Student\Anaconda3\lib\site-packages\rest_framework\decorators.py", line 50, in handler
    return func(*args, **kwargs)
  File "D:\django\docker\python2.0\src\video\views.py", line 29, in hello
    return render(request, "all_video.html", response)
  File "C:\Users\Student\Anaconda3\lib\site-packages\django\shortcuts.py", line 36, in render
    content = loader.render_to_string(template_name, context, request, using=using)
  File "C:\Users\Student\Anaconda3\lib\site-packages\django\template\loader.py", line 61, in render_to_string
    template = get_template(template_name, using=using)
  File "C:\Users\Student\Anaconda3\lib\site-packages\django\template\loader.py", line 15, in get_template
    return engine.get_template(template_name)
  File "C:\Users\Student\Anaconda3\lib\site-packages\django\template\backends\django.py", line 34, in get_template
    return Template(self.engine.get_template(template_name), self)
  File "C:\Users\Student\Anaconda3\lib\site-packages\django\template\engine.py", line 143, in get_template
    template, origin = self.find_template(template_name)
  File "C:\Users\Student\Anaconda3\lib\site-packages\django\template\engine.py", line 125, in find_template
    template = loader.get_template(name, skip=skip)
  File "C:\Users\Student\Anaconda3\lib\site-packages\django\template\loaders\base.py", line 30, in get_template
    contents, origin, origin.template_name, self.engine,
  File "C:\Users\Student\Anaconda3\lib\site-packages\django\template\base.py", line 156, in __init__
    self.nodelist = self.compile_nodelist()
  File "C:\Users\Student\Anaconda3\lib\site-packages\django\template\base.py", line 194, in compile_nodelist
    return parser.parse()
  File "C:\Users\Student\Anaconda3\lib\site-packages\django\template\base.py", line 478, in parse
    raise self.error(token, e)
  File "C:\Users\Student\Anaconda3\lib\site-packages\django\template\base.py", line 476, in parse
    compiled_result = compile_func(self, token)
  File "C:\Users\Student\Anaconda3\lib\site-packages\django\template\loader_tags.py", line 266, in do_extends
    nodelist = parser.parse()
  File "C:\Users\Student\Anaconda3\lib\site-packages\django\template\base.py", line 478, in parse
    raise self.error(token, e)
  File "C:\Users\Student\Anaconda3\lib\site-packages\django\template\base.py", line 476, in parse
    compiled_result = compile_func(self, token)
  File "C:\Users\Student\Anaconda3\lib\site-packages\django\template\loader_tags.py", line 209, in do_block
    nodelist = parser.parse(('endblock',))
  File "C:\Users\Student\Anaconda3\lib\site-packages\django\template\base.py", line 478, in parse
    raise self.error(token, e)
  File "C:\Users\Student\Anaconda3\lib\site-packages\django\template\base.py", line 476, in parse
    compiled_result = compile_func(self, token)
  File "C:\Users\Student\Anaconda3\lib\site-packages\django\template\loader_tags.py", line 311, in do_include
    (bits[0], option))
django.template.exceptions.TemplateSyntaxError: Unknown argument for 'include' tag: 'form'.
"GET /hello/ HTTP/1.1" 500 198269
Internal Server Error: /hello/
Traceback (most recent call last):
  File "C:\Users\Student\Anaconda3\lib\site-packages\django\core\handlers\exception.py", line 34, in inner
    response = get_response(request)
  File "C:\Users\Student\Anaconda3\lib\site-packages\django\core\handlers\base.py", line 115, in _get_response
    response = self.process_exception_by_middleware(e, request)
  File "C:\Users\Student\Anaconda3\lib\site-packages\django\core\handlers\base.py", line 113, in _get_response
    response = wrapped_callback(request, *callback_args, **callback_kwargs)
  File "C:\Users\Student\Anaconda3\lib\site-packages\django\views\decorators\csrf.py", line 54, in wrapped_view
    return view_func(*args, **kwargs)
  File "C:\Users\Student\Anaconda3\lib\site-packages\django\views\generic\base.py", line 71, in view
    return self.dispatch(request, *args, **kwargs)
  File "C:\Users\Student\Anaconda3\lib\site-packages\rest_framework\views.py", line 505, in dispatch
    response = self.handle_exception(exc)
  File "C:\Users\Student\Anaconda3\lib\site-packages\rest_framework\views.py", line 465, in handle_exception
    self.raise_uncaught_exception(exc)
  File "C:\Users\Student\Anaconda3\lib\site-packages\rest_framework\views.py", line 476, in raise_uncaught_exception
    raise exc
  File "C:\Users\Student\Anaconda3\lib\site-packages\rest_framework\views.py", line 502, in dispatch
    response = handler(request, *args, **kwargs)
  File "C:\Users\Student\Anaconda3\lib\site-packages\rest_framework\decorators.py", line 50, in handler
    return func(*args, **kwargs)
  File "D:\django\docker\python2.0\src\video\views.py", line 29, in hello
    return render(request, "all_video.html", response)
  File "C:\Users\Student\Anaconda3\lib\site-packages\django\shortcuts.py", line 36, in render
    content = loader.render_to_string(template_name, context, request, using=using)
  File "C:\Users\Student\Anaconda3\lib\site-packages\django\template\loader.py", line 61, in render_to_string
    template = get_template(template_name, using=using)
  File "C:\Users\Student\Anaconda3\lib\site-packages\django\template\loader.py", line 15, in get_template
    return engine.get_template(template_name)
  File "C:\Users\Student\Anaconda3\lib\site-packages\django\template\backends\django.py", line 34, in get_template
    return Template(self.engine.get_template(template_name), self)
  File "C:\Users\Student\Anaconda3\lib\site-packages\django\template\engine.py", line 143, in get_template
    template, origin = self.find_template(template_name)
  File "C:\Users\Student\Anaconda3\lib\site-packages\django\template\engine.py", line 125, in find_template
    template = loader.get_template(name, skip=skip)
  File "C:\Users\Student\Anaconda3\lib\site-packages\django\template\loaders\base.py", line 30, in get_template
    contents, origin, origin.template_name, self.engine,
  File "C:\Users\Student\Anaconda3\lib\site-packages\django\template\base.py", line 156, in __init__
    self.nodelist = self.compile_nodelist()
  File "C:\Users\Student\Anaconda3\lib\site-packages\django\template\base.py", line 194, in compile_nodelist
    return parser.parse()
  File "C:\Users\Student\Anaconda3\lib\site-packages\django\template\base.py", line 478, in parse
    raise self.error(token, e)
  File "C:\Users\Student\Anaconda3\lib\site-packages\django\template\base.py", line 476, in parse
    compiled_result = compile_func(self, token)
  File "C:\Users\Student\Anaconda3\lib\site-packages\django\template\loader_tags.py", line 266, in do_extends
    nodelist = parser.parse()
  File "C:\Users\Student\Anaconda3\lib\site-packages\django\template\base.py", line 478, in parse
    raise self.error(token, e)
  File "C:\Users\Student\Anaconda3\lib\site-packages\django\template\base.py", line 476, in parse
    compiled_result = compile_func(self, token)
  File "C:\Users\Student\Anaconda3\lib\site-packages\django\template\loader_tags.py", line 209, in do_block
    nodelist = parser.parse(('endblock',))
  File "C:\Users\Student\Anaconda3\lib\site-packages\django\template\base.py", line 478, in parse
    raise self.error(token, e)
  File "C:\Users\Student\Anaconda3\lib\site-packages\django\template\base.py", line 476, in parse
    compiled_result = compile_func(self, token)
  File "C:\Users\Student\Anaconda3\lib\site-packages\django\template\loader_tags.py", line 311, in do_include
    (bits[0], option))
django.template.exceptions.TemplateSyntaxError: Unknown argument for 'include' tag: "'form'".
"GET /hello/ HTTP/1.1" 500 198439
Not Found: /favicon.ico
"GET /favicon.ico HTTP/1.1" 404 2522
Internal Server Error: /hello/
Traceback (most recent call last):
  File "C:\Users\Student\Anaconda3\lib\site-packages\django\core\handlers\exception.py", line 34, in inner
    response = get_response(request)
  File "C:\Users\Student\Anaconda3\lib\site-packages\django\core\handlers\base.py", line 115, in _get_response
    response = self.process_exception_by_middleware(e, request)
  File "C:\Users\Student\Anaconda3\lib\site-packages\django\core\handlers\base.py", line 113, in _get_response
    response = wrapped_callback(request, *callback_args, **callback_kwargs)
  File "C:\Users\Student\Anaconda3\lib\site-packages\django\views\decorators\csrf.py", line 54, in wrapped_view
    return view_func(*args, **kwargs)
  File "C:\Users\Student\Anaconda3\lib\site-packages\django\views\generic\base.py", line 71, in view
    return self.dispatch(request, *args, **kwargs)
  File "C:\Users\Student\Anaconda3\lib\site-packages\rest_framework\views.py", line 505, in dispatch
    response = self.handle_exception(exc)
  File "C:\Users\Student\Anaconda3\lib\site-packages\rest_framework\views.py", line 465, in handle_exception
    self.raise_uncaught_exception(exc)
  File "C:\Users\Student\Anaconda3\lib\site-packages\rest_framework\views.py", line 476, in raise_uncaught_exception
    raise exc
  File "C:\Users\Student\Anaconda3\lib\site-packages\rest_framework\views.py", line 502, in dispatch
    response = handler(request, *args, **kwargs)
  File "C:\Users\Student\Anaconda3\lib\site-packages\rest_framework\decorators.py", line 50, in handler
    return func(*args, **kwargs)
  File "D:\django\docker\python2.0\src\video\views.py", line 20, in hello
    return render(request, "all_video.html", response)
  File "C:\Users\Student\Anaconda3\lib\site-packages\django\shortcuts.py", line 36, in render
    content = loader.render_to_string(template_name, context, request, using=using)
  File "C:\Users\Student\Anaconda3\lib\site-packages\django\template\loader.py", line 62, in render_to_string
    return template.render(context, request)
  File "C:\Users\Student\Anaconda3\lib\site-packages\django\template\backends\django.py", line 61, in render
    return self.template.render(context)
  File "C:\Users\Student\Anaconda3\lib\site-packages\django\template\base.py", line 171, in render
    return self._render(context)
  File "C:\Users\Student\Anaconda3\lib\site-packages\django\template\base.py", line 163, in _render
    return self.nodelist.render(context)
  File "C:\Users\Student\Anaconda3\lib\site-packages\django\template\base.py", line 937, in render
    bit = node.render_annotated(context)
  File "C:\Users\Student\Anaconda3\lib\site-packages\django\template\base.py", line 904, in render_annotated
    return self.render(context)
  File "C:\Users\Student\Anaconda3\lib\site-packages\django\template\loader_tags.py", line 150, in render
    return compiled_parent._render(context)
  File "C:\Users\Student\Anaconda3\lib\site-packages\django\template\base.py", line 163, in _render
    return self.nodelist.render(context)
  File "C:\Users\Student\Anaconda3\lib\site-packages\django\template\base.py", line 937, in render
    bit = node.render_annotated(context)
  File "C:\Users\Student\Anaconda3\lib\site-packages\django\template\base.py", line 904, in render_annotated
    return self.render(context)
  File "C:\Users\Student\Anaconda3\lib\site-packages\django\template\loader_tags.py", line 62, in render
    result = block.nodelist.render(context)
  File "C:\Users\Student\Anaconda3\lib\site-packages\django\template\base.py", line 937, in render
    bit = node.render_annotated(context)
  File "C:\Users\Student\Anaconda3\lib\site-packages\django\template\base.py", line 904, in render_annotated
    return self.render(context)
  File "C:\Users\Student\Anaconda3\lib\site-packages\django\template\defaulttags.py", line 209, in render
    nodelist.append(node.render_annotated(context))
  File "C:\Users\Student\Anaconda3\lib\site-packages\django\template\base.py", line 904, in render_annotated
    return self.render(context)
  File "C:\Users\Student\Anaconda3\lib\site-packages\django\template\defaulttags.py", line 443, in render
    url = reverse(view_name, args=args, kwargs=kwargs, current_app=current_app)
  File "C:\Users\Student\Anaconda3\lib\site-packages\django\urls\base.py", line 90, in reverse
    return iri_to_uri(resolver._reverse_with_prefix(view, prefix, *args, **kwargs))
  File "C:\Users\Student\Anaconda3\lib\site-packages\django\urls\resolvers.py", line 668, in _reverse_with_prefix
    raise NoReverseMatch(msg)
django.urls.exceptions.NoReverseMatch: Reverse for 'add_comment' with keyword arguments '{'slug': 'oxxxymiron-gorod-pod-podoshvoj-2015'}' not found. 1 pattern(s) tried: ['hello/add_comment_blyt/<str:slug>/$']
"GET /hello/ HTTP/1.1" 500 236264
Internal Server Error: /hello/add_comment_blyt/castlevania-blood-in-the-wateramv/
Traceback (most recent call last):
  File "C:\Users\Student\Anaconda3\lib\site-packages\django\utils\datastructures.py", line 78, in __getitem__
    list_ = super().__getitem__(key)
KeyError: 'text'

During handling of the above exception, another exception occurred:

Traceback (most recent call last):
  File "C:\Users\Student\Anaconda3\lib\site-packages\django\core\handlers\exception.py", line 34, in inner
    response = get_response(request)
  File "C:\Users\Student\Anaconda3\lib\site-packages\django\core\handlers\base.py", line 115, in _get_response
    response = self.process_exception_by_middleware(e, request)
  File "C:\Users\Student\Anaconda3\lib\site-packages\django\core\handlers\base.py", line 113, in _get_response
    response = wrapped_callback(request, *callback_args, **callback_kwargs)
  File "D:\django\docker\python2.0\src\video\views.py", line 32, in add_comment
    text = request.GET['text']
  File "C:\Users\Student\Anaconda3\lib\site-packages\django\utils\datastructures.py", line 80, in __getitem__
    raise MultiValueDictKeyError(key)
django.utils.datastructures.MultiValueDictKeyError: 'text'
Internal Server Error: /hello/add_comment_blyt/castlevania-blood-in-the-wateramv/
Traceback (most recent call last):
  File "C:\Users\Student\Anaconda3\lib\site-packages\django\utils\datastructures.py", line 78, in __getitem__
    list_ = super().__getitem__(key)
KeyError: 'text'

During handling of the above exception, another exception occurred:

Traceback (most recent call last):
  File "C:\Users\Student\Anaconda3\lib\site-packages\django\core\handlers\exception.py", line 34, in inner
    response = get_response(request)
  File "C:\Users\Student\Anaconda3\lib\site-packages\django\core\handlers\base.py", line 115, in _get_response
    response = self.process_exception_by_middleware(e, request)
  File "C:\Users\Student\Anaconda3\lib\site-packages\django\core\handlers\base.py", line 113, in _get_response
    response = wrapped_callback(request, *callback_args, **callback_kwargs)
  File "D:\django\docker\python2.0\src\video\views.py", line 32, in add_comment
    text = request.GET['text']
  File "C:\Users\Student\Anaconda3\lib\site-packages\django\utils\datastructures.py", line 80, in __getitem__
    raise MultiValueDictKeyError(key)
django.utils.datastructures.MultiValueDictKeyError: 'text'
"POST /hello/add_comment_blyt/castlevania-blood-in-the-wateramv/ HTTP/1.1" 500 77315
"POST /hello/add_comment_blyt/castlevania-blood-in-the-wateramv/ HTTP/1.1" 500 77315
"POST /hello/add_comment_blyt/castlevania-blood-in-the-wateramv/ HTTP/1.1" 500 59
"POST /hello/add_comment_blyt/castlevania-blood-in-the-wateramv/ HTTP/1.1" 500 59
Internal Server Error: /hello/add_comment_blyt/castlevania-blood-in-the-wateramv/
Traceback (most recent call last):
  File "C:\Users\Student\Anaconda3\lib\site-packages\django\utils\datastructures.py", line 78, in __getitem__
    list_ = super().__getitem__(key)
KeyError: 'text'

During handling of the above exception, another exception occurred:

Traceback (most recent call last):
  File "C:\Users\Student\Anaconda3\lib\site-packages\django\core\handlers\exception.py", line 34, in inner
    response = get_response(request)
  File "C:\Users\Student\Anaconda3\lib\site-packages\django\core\handlers\base.py", line 115, in _get_response
    response = self.process_exception_by_middleware(e, request)
  File "C:\Users\Student\Anaconda3\lib\site-packages\django\core\handlers\base.py", line 113, in _get_response
    response = wrapped_callback(request, *callback_args, **callback_kwargs)
  File "D:\django\docker\python2.0\src\video\views.py", line 32, in add_comment
    text = request.GET['text']
  File "C:\Users\Student\Anaconda3\lib\site-packages\django\utils\datastructures.py", line 80, in __getitem__
    raise MultiValueDictKeyError(key)
django.utils.datastructures.MultiValueDictKeyError: 'text'
"POST /hello/add_comment_blyt/castlevania-blood-in-the-wateramv/ HTTP/1.1" 500 77315
Internal Server Error: /hello/
Traceback (most recent call last):
  File "C:\Users\Student\Anaconda3\lib\site-packages\django\core\handlers\exception.py", line 34, in inner
    response = get_response(request)
  File "C:\Users\Student\Anaconda3\lib\site-packages\django\core\handlers\base.py", line 115, in _get_response
    response = self.process_exception_by_middleware(e, request)
  File "C:\Users\Student\Anaconda3\lib\site-packages\django\core\handlers\base.py", line 113, in _get_response
    response = wrapped_callback(request, *callback_args, **callback_kwargs)
  File "C:\Users\Student\Anaconda3\lib\site-packages\django\views\decorators\csrf.py", line 54, in wrapped_view
    return view_func(*args, **kwargs)
  File "C:\Users\Student\Anaconda3\lib\site-packages\django\views\generic\base.py", line 71, in view
    return self.dispatch(request, *args, **kwargs)
  File "C:\Users\Student\Anaconda3\lib\site-packages\rest_framework\views.py", line 505, in dispatch
    response = self.handle_exception(exc)
  File "C:\Users\Student\Anaconda3\lib\site-packages\rest_framework\views.py", line 465, in handle_exception
    self.raise_uncaught_exception(exc)
  File "C:\Users\Student\Anaconda3\lib\site-packages\rest_framework\views.py", line 476, in raise_uncaught_exception
    raise exc
  File "C:\Users\Student\Anaconda3\lib\site-packages\rest_framework\views.py", line 502, in dispatch
    response = handler(request, *args, **kwargs)
  File "C:\Users\Student\Anaconda3\lib\site-packages\rest_framework\decorators.py", line 50, in handler
    return func(*args, **kwargs)
  File "D:\django\docker\python2.0\src\video\views.py", line 20, in hello
    return render(request, "all_video.html", response)
  File "C:\Users\Student\Anaconda3\lib\site-packages\django\shortcuts.py", line 36, in render
    content = loader.render_to_string(template_name, context, request, using=using)
  File "C:\Users\Student\Anaconda3\lib\site-packages\django\template\loader.py", line 62, in render_to_string
    return template.render(context, request)
  File "C:\Users\Student\Anaconda3\lib\site-packages\django\template\backends\django.py", line 61, in render
    return self.template.render(context)
  File "C:\Users\Student\Anaconda3\lib\site-packages\django\template\base.py", line 171, in render
    return self._render(context)
  File "C:\Users\Student\Anaconda3\lib\site-packages\django\template\base.py", line 163, in _render
    return self.nodelist.render(context)
  File "C:\Users\Student\Anaconda3\lib\site-packages\django\template\base.py", line 937, in render
    bit = node.render_annotated(context)
  File "C:\Users\Student\Anaconda3\lib\site-packages\django\template\base.py", line 904, in render_annotated
    return self.render(context)
  File "C:\Users\Student\Anaconda3\lib\site-packages\django\template\loader_tags.py", line 150, in render
    return compiled_parent._render(context)
  File "C:\Users\Student\Anaconda3\lib\site-packages\django\template\base.py", line 163, in _render
    return self.nodelist.render(context)
  File "C:\Users\Student\Anaconda3\lib\site-packages\django\template\base.py", line 937, in render
    bit = node.render_annotated(context)
  File "C:\Users\Student\Anaconda3\lib\site-packages\django\template\base.py", line 904, in render_annotated
    return self.render(context)
  File "C:\Users\Student\Anaconda3\lib\site-packages\django\template\loader_tags.py", line 62, in render
    result = block.nodelist.render(context)
  File "C:\Users\Student\Anaconda3\lib\site-packages\django\template\base.py", line 937, in render
    bit = node.render_annotated(context)
  File "C:\Users\Student\Anaconda3\lib\site-packages\django\template\base.py", line 904, in render_annotated
    return self.render(context)
  File "C:\Users\Student\Anaconda3\lib\site-packages\django\template\base.py", line 993, in render
    return render_value_in_context(output, context)
  File "C:\Users\Student\Anaconda3\lib\site-packages\django\template\base.py", line 972, in render_value_in_context
    value = str(value)
  File "C:\Users\Student\Anaconda3\lib\site-packages\django\utils\html.py", line 388, in <lambda>
    klass.__str__ = lambda self: mark_safe(klass_str(self))
  File "C:\Users\Student\Anaconda3\lib\site-packages\django\forms\forms.py", line 142, in __str__
    return self.as_table()
  File "C:\Users\Student\Anaconda3\lib\site-packages\django\forms\forms.py", line 284, in as_table
    errors_on_separate_row=False,
  File "C:\Users\Student\Anaconda3\lib\site-packages\django\forms\forms.py", line 209, in _html_output
    if bf.is_hidden:
  File "C:\Users\Student\Anaconda3\lib\site-packages\django\forms\boundfield.py", line 182, in is_hidden
    return self.field.widget.is_hidden
AttributeError: 'SlugField' object has no attribute 'is_hidden'
"GET /hello/ HTTP/1.1" 500 240458
Internal Server Error: /hello/
Traceback (most recent call last):
  File "C:\Users\Student\Anaconda3\lib\site-packages\django\core\handlers\exception.py", line 34, in inner
    response = get_response(request)
  File "C:\Users\Student\Anaconda3\lib\site-packages\django\core\handlers\base.py", line 115, in _get_response
    response = self.process_exception_by_middleware(e, request)
  File "C:\Users\Student\Anaconda3\lib\site-packages\django\core\handlers\base.py", line 113, in _get_response
    response = wrapped_callback(request, *callback_args, **callback_kwargs)
  File "C:\Users\Student\Anaconda3\lib\site-packages\django\views\decorators\csrf.py", line 54, in wrapped_view
    return view_func(*args, **kwargs)
  File "C:\Users\Student\Anaconda3\lib\site-packages\django\views\generic\base.py", line 71, in view
    return self.dispatch(request, *args, **kwargs)
  File "C:\Users\Student\Anaconda3\lib\site-packages\rest_framework\views.py", line 505, in dispatch
    response = self.handle_exception(exc)
  File "C:\Users\Student\Anaconda3\lib\site-packages\rest_framework\views.py", line 465, in handle_exception
    self.raise_uncaught_exception(exc)
  File "C:\Users\Student\Anaconda3\lib\site-packages\rest_framework\views.py", line 476, in raise_uncaught_exception
    raise exc
  File "C:\Users\Student\Anaconda3\lib\site-packages\rest_framework\views.py", line 502, in dispatch
    response = handler(request, *args, **kwargs)
  File "C:\Users\Student\Anaconda3\lib\site-packages\rest_framework\decorators.py", line 50, in handler
    return func(*args, **kwargs)
  File "D:\django\docker\python2.0\src\video\views.py", line 20, in hello
    return render(request, "all_video.html", response)
  File "C:\Users\Student\Anaconda3\lib\site-packages\django\shortcuts.py", line 36, in render
    content = loader.render_to_string(template_name, context, request, using=using)
  File "C:\Users\Student\Anaconda3\lib\site-packages\django\template\loader.py", line 62, in render_to_string
    return template.render(context, request)
  File "C:\Users\Student\Anaconda3\lib\site-packages\django\template\backends\django.py", line 61, in render
    return self.template.render(context)
  File "C:\Users\Student\Anaconda3\lib\site-packages\django\template\base.py", line 171, in render
    return self._render(context)
  File "C:\Users\Student\Anaconda3\lib\site-packages\django\template\base.py", line 163, in _render
    return self.nodelist.render(context)
  File "C:\Users\Student\Anaconda3\lib\site-packages\django\template\base.py", line 937, in render
    bit = node.render_annotated(context)
  File "C:\Users\Student\Anaconda3\lib\site-packages\django\template\base.py", line 904, in render_annotated
    return self.render(context)
  File "C:\Users\Student\Anaconda3\lib\site-packages\django\template\loader_tags.py", line 150, in render
    return compiled_parent._render(context)
  File "C:\Users\Student\Anaconda3\lib\site-packages\django\template\base.py", line 163, in _render
    return self.nodelist.render(context)
  File "C:\Users\Student\Anaconda3\lib\site-packages\django\template\base.py", line 937, in render
    bit = node.render_annotated(context)
  File "C:\Users\Student\Anaconda3\lib\site-packages\django\template\base.py", line 904, in render_annotated
    return self.render(context)
  File "C:\Users\Student\Anaconda3\lib\site-packages\django\template\loader_tags.py", line 62, in render
    result = block.nodelist.render(context)
  File "C:\Users\Student\Anaconda3\lib\site-packages\django\template\base.py", line 937, in render
    bit = node.render_annotated(context)
  File "C:\Users\Student\Anaconda3\lib\site-packages\django\template\base.py", line 904, in render_annotated
    return self.render(context)
  File "C:\Users\Student\Anaconda3\lib\site-packages\django\template\base.py", line 993, in render
    return render_value_in_context(output, context)
  File "C:\Users\Student\Anaconda3\lib\site-packages\django\template\base.py", line 972, in render_value_in_context
    value = str(value)
  File "C:\Users\Student\Anaconda3\lib\site-packages\django\utils\html.py", line 388, in <lambda>
    klass.__str__ = lambda self: mark_safe(klass_str(self))
  File "C:\Users\Student\Anaconda3\lib\site-packages\django\forms\boundfield.py", line 33, in __str__
    return self.as_widget()
  File "C:\Users\Student\Anaconda3\lib\site-packages\django\forms\boundfield.py", line 86, in as_widget
    attrs = self.build_widget_attrs(attrs, widget)
  File "C:\Users\Student\Anaconda3\lib\site-packages\django\forms\boundfield.py", line 221, in build_widget_attrs
    if widget.use_required_attribute(self.initial) and self.field.required and self.form.use_required_attribute:
AttributeError: 'SlugField' object has no attribute 'use_required_attribute'
"GET /hello/ HTTP/1.1" 500 235073
Internal Server Error: /hello/
Traceback (most recent call last):
  File "C:\Users\Student\Anaconda3\lib\site-packages\django\core\handlers\exception.py", line 34, in inner
    response = get_response(request)
  File "C:\Users\Student\Anaconda3\lib\site-packages\django\core\handlers\base.py", line 115, in _get_response
    response = self.process_exception_by_middleware(e, request)
  File "C:\Users\Student\Anaconda3\lib\site-packages\django\core\handlers\base.py", line 113, in _get_response
    response = wrapped_callback(request, *callback_args, **callback_kwargs)
  File "C:\Users\Student\Anaconda3\lib\site-packages\django\views\decorators\csrf.py", line 54, in wrapped_view
    return view_func(*args, **kwargs)
  File "C:\Users\Student\Anaconda3\lib\site-packages\django\views\generic\base.py", line 71, in view
    return self.dispatch(request, *args, **kwargs)
  File "C:\Users\Student\Anaconda3\lib\site-packages\rest_framework\views.py", line 505, in dispatch
    response = self.handle_exception(exc)
  File "C:\Users\Student\Anaconda3\lib\site-packages\rest_framework\views.py", line 465, in handle_exception
    self.raise_uncaught_exception(exc)
  File "C:\Users\Student\Anaconda3\lib\site-packages\rest_framework\views.py", line 476, in raise_uncaught_exception
    raise exc
  File "C:\Users\Student\Anaconda3\lib\site-packages\rest_framework\views.py", line 502, in dispatch
    response = handler(request, *args, **kwargs)
  File "C:\Users\Student\Anaconda3\lib\site-packages\rest_framework\decorators.py", line 50, in handler
    return func(*args, **kwargs)
  File "D:\django\docker\python2.0\src\video\views.py", line 20, in hello
    return render(request, "all_video.html", response)
  File "C:\Users\Student\Anaconda3\lib\site-packages\django\shortcuts.py", line 36, in render
    content = loader.render_to_string(template_name, context, request, using=using)
  File "C:\Users\Student\Anaconda3\lib\site-packages\django\template\loader.py", line 62, in render_to_string
    return template.render(context, request)
  File "C:\Users\Student\Anaconda3\lib\site-packages\django\template\backends\django.py", line 61, in render
    return self.template.render(context)
  File "C:\Users\Student\Anaconda3\lib\site-packages\django\template\base.py", line 171, in render
    return self._render(context)
  File "C:\Users\Student\Anaconda3\lib\site-packages\django\template\base.py", line 163, in _render
    return self.nodelist.render(context)
  File "C:\Users\Student\Anaconda3\lib\site-packages\django\template\base.py", line 937, in render
    bit = node.render_annotated(context)
  File "C:\Users\Student\Anaconda3\lib\site-packages\django\template\base.py", line 904, in render_annotated
    return self.render(context)
  File "C:\Users\Student\Anaconda3\lib\site-packages\django\template\loader_tags.py", line 150, in render
    return compiled_parent._render(context)
  File "C:\Users\Student\Anaconda3\lib\site-packages\django\template\base.py", line 163, in _render
    return self.nodelist.render(context)
  File "C:\Users\Student\Anaconda3\lib\site-packages\django\template\base.py", line 937, in render
    bit = node.render_annotated(context)
  File "C:\Users\Student\Anaconda3\lib\site-packages\django\template\base.py", line 904, in render_annotated
    return self.render(context)
  File "C:\Users\Student\Anaconda3\lib\site-packages\django\template\loader_tags.py", line 62, in render
    result = block.nodelist.render(context)
  File "C:\Users\Student\Anaconda3\lib\site-packages\django\template\base.py", line 937, in render
    bit = node.render_annotated(context)
  File "C:\Users\Student\Anaconda3\lib\site-packages\django\template\base.py", line 904, in render_annotated
    return self.render(context)
  File "C:\Users\Student\Anaconda3\lib\site-packages\django\template\base.py", line 993, in render
    return render_value_in_context(output, context)
  File "C:\Users\Student\Anaconda3\lib\site-packages\django\template\base.py", line 972, in render_value_in_context
    value = str(value)
  File "C:\Users\Student\Anaconda3\lib\site-packages\django\utils\html.py", line 388, in <lambda>
    klass.__str__ = lambda self: mark_safe(klass_str(self))
  File "C:\Users\Student\Anaconda3\lib\site-packages\django\forms\boundfield.py", line 33, in __str__
    return self.as_widget()
  File "C:\Users\Student\Anaconda3\lib\site-packages\django\forms\boundfield.py", line 86, in as_widget
    attrs = self.build_widget_attrs(attrs, widget)
  File "C:\Users\Student\Anaconda3\lib\site-packages\django\forms\boundfield.py", line 221, in build_widget_attrs
    if widget.use_required_attribute(self.initial) and self.field.required and self.form.use_required_attribute:
AttributeError: 'URLField' object has no attribute 'use_required_attribute'
"GET /hello/ HTTP/1.1" 500 234975
Internal Server Error: /hello/
Traceback (most recent call last):
  File "C:\Users\Student\Anaconda3\lib\site-packages\django\core\handlers\exception.py", line 34, in inner
    response = get_response(request)
  File "C:\Users\Student\Anaconda3\lib\site-packages\django\core\handlers\base.py", line 115, in _get_response
    response = self.process_exception_by_middleware(e, request)
  File "C:\Users\Student\Anaconda3\lib\site-packages\django\core\handlers\base.py", line 113, in _get_response
    response = wrapped_callback(request, *callback_args, **callback_kwargs)
  File "C:\Users\Student\Anaconda3\lib\site-packages\django\views\decorators\csrf.py", line 54, in wrapped_view
    return view_func(*args, **kwargs)
  File "C:\Users\Student\Anaconda3\lib\site-packages\django\views\generic\base.py", line 71, in view
    return self.dispatch(request, *args, **kwargs)
  File "C:\Users\Student\Anaconda3\lib\site-packages\rest_framework\views.py", line 505, in dispatch
    response = self.handle_exception(exc)
  File "C:\Users\Student\Anaconda3\lib\site-packages\rest_framework\views.py", line 465, in handle_exception
    self.raise_uncaught_exception(exc)
  File "C:\Users\Student\Anaconda3\lib\site-packages\rest_framework\views.py", line 476, in raise_uncaught_exception
    raise exc
  File "C:\Users\Student\Anaconda3\lib\site-packages\rest_framework\views.py", line 502, in dispatch
    response = handler(request, *args, **kwargs)
  File "C:\Users\Student\Anaconda3\lib\site-packages\rest_framework\decorators.py", line 50, in handler
    return func(*args, **kwargs)
  File "D:\django\docker\python2.0\src\video\views.py", line 20, in hello
    return render(request, "all_video.html", response)
  File "C:\Users\Student\Anaconda3\lib\site-packages\django\shortcuts.py", line 36, in render
    content = loader.render_to_string(template_name, context, request, using=using)
  File "C:\Users\Student\Anaconda3\lib\site-packages\django\template\loader.py", line 62, in render_to_string
    return template.render(context, request)
  File "C:\Users\Student\Anaconda3\lib\site-packages\django\template\backends\django.py", line 61, in render
    return self.template.render(context)
  File "C:\Users\Student\Anaconda3\lib\site-packages\django\template\base.py", line 171, in render
    return self._render(context)
  File "C:\Users\Student\Anaconda3\lib\site-packages\django\template\base.py", line 163, in _render
    return self.nodelist.render(context)
  File "C:\Users\Student\Anaconda3\lib\site-packages\django\template\base.py", line 937, in render
    bit = node.render_annotated(context)
  File "C:\Users\Student\Anaconda3\lib\site-packages\django\template\base.py", line 904, in render_annotated
    return self.render(context)
  File "C:\Users\Student\Anaconda3\lib\site-packages\django\template\loader_tags.py", line 150, in render
    return compiled_parent._render(context)
  File "C:\Users\Student\Anaconda3\lib\site-packages\django\template\base.py", line 163, in _render
    return self.nodelist.render(context)
  File "C:\Users\Student\Anaconda3\lib\site-packages\django\template\base.py", line 937, in render
    bit = node.render_annotated(context)
  File "C:\Users\Student\Anaconda3\lib\site-packages\django\template\base.py", line 904, in render_annotated
    return self.render(context)
  File "C:\Users\Student\Anaconda3\lib\site-packages\django\template\loader_tags.py", line 62, in render
    result = block.nodelist.render(context)
  File "C:\Users\Student\Anaconda3\lib\site-packages\django\template\base.py", line 937, in render
    bit = node.render_annotated(context)
  File "C:\Users\Student\Anaconda3\lib\site-packages\django\template\base.py", line 904, in render_annotated
    return self.render(context)
  File "C:\Users\Student\Anaconda3\lib\site-packages\django\template\base.py", line 993, in render
    return render_value_in_context(output, context)
  File "C:\Users\Student\Anaconda3\lib\site-packages\django\template\base.py", line 972, in render_value_in_context
    value = str(value)
  File "C:\Users\Student\Anaconda3\lib\site-packages\django\utils\html.py", line 388, in <lambda>
    klass.__str__ = lambda self: mark_safe(klass_str(self))
  File "C:\Users\Student\Anaconda3\lib\site-packages\django\forms\boundfield.py", line 33, in __str__
    return self.as_widget()
  File "C:\Users\Student\Anaconda3\lib\site-packages\django\forms\boundfield.py", line 86, in as_widget
    attrs = self.build_widget_attrs(attrs, widget)
  File "C:\Users\Student\Anaconda3\lib\site-packages\django\forms\boundfield.py", line 221, in build_widget_attrs
    if widget.use_required_attribute(self.initial) and self.field.required and self.form.use_required_attribute:
AttributeError: 'URLField' object has no attribute 'use_required_attribute'
"GET /hello/ HTTP/1.1" 500 234975
Internal Server Error: /hello/
Traceback (most recent call last):
  File "C:\Users\Student\Anaconda3\lib\site-packages\django\core\handlers\exception.py", line 34, in inner
    response = get_response(request)
  File "C:\Users\Student\Anaconda3\lib\site-packages\django\core\handlers\base.py", line 115, in _get_response
    response = self.process_exception_by_middleware(e, request)
  File "C:\Users\Student\Anaconda3\lib\site-packages\django\core\handlers\base.py", line 113, in _get_response
    response = wrapped_callback(request, *callback_args, **callback_kwargs)
  File "C:\Users\Student\Anaconda3\lib\site-packages\django\views\decorators\csrf.py", line 54, in wrapped_view
    return view_func(*args, **kwargs)
  File "C:\Users\Student\Anaconda3\lib\site-packages\django\views\generic\base.py", line 71, in view
    return self.dispatch(request, *args, **kwargs)
  File "C:\Users\Student\Anaconda3\lib\site-packages\rest_framework\views.py", line 505, in dispatch
    response = self.handle_exception(exc)
  File "C:\Users\Student\Anaconda3\lib\site-packages\rest_framework\views.py", line 465, in handle_exception
    self.raise_uncaught_exception(exc)
  File "C:\Users\Student\Anaconda3\lib\site-packages\rest_framework\views.py", line 476, in raise_uncaught_exception
    raise exc
  File "C:\Users\Student\Anaconda3\lib\site-packages\rest_framework\views.py", line 502, in dispatch
    response = handler(request, *args, **kwargs)
  File "C:\Users\Student\Anaconda3\lib\site-packages\rest_framework\decorators.py", line 50, in handler
    return func(*args, **kwargs)
  File "D:\django\docker\python2.0\src\video\views.py", line 20, in hello
    return render(request, "all_video.html", response)
  File "C:\Users\Student\Anaconda3\lib\site-packages\django\shortcuts.py", line 36, in render
    content = loader.render_to_string(template_name, context, request, using=using)
  File "C:\Users\Student\Anaconda3\lib\site-packages\django\template\loader.py", line 62, in render_to_string
    return template.render(context, request)
  File "C:\Users\Student\Anaconda3\lib\site-packages\django\template\backends\django.py", line 61, in render
    return self.template.render(context)
  File "C:\Users\Student\Anaconda3\lib\site-packages\django\template\base.py", line 171, in render
    return self._render(context)
  File "C:\Users\Student\Anaconda3\lib\site-packages\django\template\base.py", line 163, in _render
    return self.nodelist.render(context)
  File "C:\Users\Student\Anaconda3\lib\site-packages\django\template\base.py", line 937, in render
    bit = node.render_annotated(context)
  File "C:\Users\Student\Anaconda3\lib\site-packages\django\template\base.py", line 904, in render_annotated
    return self.render(context)
  File "C:\Users\Student\Anaconda3\lib\site-packages\django\template\loader_tags.py", line 150, in render
    return compiled_parent._render(context)
  File "C:\Users\Student\Anaconda3\lib\site-packages\django\template\base.py", line 163, in _render
    return self.nodelist.render(context)
  File "C:\Users\Student\Anaconda3\lib\site-packages\django\template\base.py", line 937, in render
    bit = node.render_annotated(context)
  File "C:\Users\Student\Anaconda3\lib\site-packages\django\template\base.py", line 904, in render_annotated
    return self.render(context)
  File "C:\Users\Student\Anaconda3\lib\site-packages\django\template\loader_tags.py", line 62, in render
    result = block.nodelist.render(context)
  File "C:\Users\Student\Anaconda3\lib\site-packages\django\template\base.py", line 937, in render
    bit = node.render_annotated(context)
  File "C:\Users\Student\Anaconda3\lib\site-packages\django\template\base.py", line 904, in render_annotated
    return self.render(context)
  File "C:\Users\Student\Anaconda3\lib\site-packages\django\template\defaulttags.py", line 443, in render
    url = reverse(view_name, args=args, kwargs=kwargs, current_app=current_app)
  File "C:\Users\Student\Anaconda3\lib\site-packages\django\urls\base.py", line 90, in reverse
    return iri_to_uri(resolver._reverse_with_prefix(view, prefix, *args, **kwargs))
  File "C:\Users\Student\Anaconda3\lib\site-packages\django\urls\resolvers.py", line 668, in _reverse_with_prefix
    raise NoReverseMatch(msg)
django.urls.exceptions.NoReverseMatch: Reverse for 'video_form' with keyword arguments '{'slug': ''}' not found. 1 pattern(s) tried: ['form_video/(?P<slug>[-\\w]+)/$']
"GET /hello/ HTTP/1.1" 500 228063
Internal Server Error: /hello/
Traceback (most recent call last):
  File "C:\Users\Student\Anaconda3\lib\site-packages\django\core\handlers\exception.py", line 34, in inner
    response = get_response(request)
  File "C:\Users\Student\Anaconda3\lib\site-packages\django\core\handlers\base.py", line 115, in _get_response
    response = self.process_exception_by_middleware(e, request)
  File "C:\Users\Student\Anaconda3\lib\site-packages\django\core\handlers\base.py", line 113, in _get_response
    response = wrapped_callback(request, *callback_args, **callback_kwargs)
  File "C:\Users\Student\Anaconda3\lib\site-packages\django\views\decorators\csrf.py", line 54, in wrapped_view
    return view_func(*args, **kwargs)
  File "C:\Users\Student\Anaconda3\lib\site-packages\django\views\generic\base.py", line 71, in view
    return self.dispatch(request, *args, **kwargs)
  File "C:\Users\Student\Anaconda3\lib\site-packages\rest_framework\views.py", line 505, in dispatch
    response = self.handle_exception(exc)
  File "C:\Users\Student\Anaconda3\lib\site-packages\rest_framework\views.py", line 465, in handle_exception
    self.raise_uncaught_exception(exc)
  File "C:\Users\Student\Anaconda3\lib\site-packages\rest_framework\views.py", line 476, in raise_uncaught_exception
    raise exc
  File "C:\Users\Student\Anaconda3\lib\site-packages\rest_framework\views.py", line 502, in dispatch
    response = handler(request, *args, **kwargs)
  File "C:\Users\Student\Anaconda3\lib\site-packages\rest_framework\decorators.py", line 50, in handler
    return func(*args, **kwargs)
  File "D:\django\docker\python2.0\src\video\views.py", line 20, in hello
    return render(request, "all_video.html", response)
  File "C:\Users\Student\Anaconda3\lib\site-packages\django\shortcuts.py", line 36, in render
    content = loader.render_to_string(template_name, context, request, using=using)
  File "C:\Users\Student\Anaconda3\lib\site-packages\django\template\loader.py", line 62, in render_to_string
    return template.render(context, request)
  File "C:\Users\Student\Anaconda3\lib\site-packages\django\template\backends\django.py", line 61, in render
    return self.template.render(context)
  File "C:\Users\Student\Anaconda3\lib\site-packages\django\template\base.py", line 171, in render
    return self._render(context)
  File "C:\Users\Student\Anaconda3\lib\site-packages\django\template\base.py", line 163, in _render
    return self.nodelist.render(context)
  File "C:\Users\Student\Anaconda3\lib\site-packages\django\template\base.py", line 937, in render
    bit = node.render_annotated(context)
  File "C:\Users\Student\Anaconda3\lib\site-packages\django\template\base.py", line 904, in render_annotated
    return self.render(context)
  File "C:\Users\Student\Anaconda3\lib\site-packages\django\template\loader_tags.py", line 150, in render
    return compiled_parent._render(context)
  File "C:\Users\Student\Anaconda3\lib\site-packages\django\template\base.py", line 163, in _render
    return self.nodelist.render(context)
  File "C:\Users\Student\Anaconda3\lib\site-packages\django\template\base.py", line 937, in render
    bit = node.render_annotated(context)
  File "C:\Users\Student\Anaconda3\lib\site-packages\django\template\base.py", line 904, in render_annotated
    return self.render(context)
  File "C:\Users\Student\Anaconda3\lib\site-packages\django\template\loader_tags.py", line 62, in render
    result = block.nodelist.render(context)
  File "C:\Users\Student\Anaconda3\lib\site-packages\django\template\base.py", line 937, in render
    bit = node.render_annotated(context)
  File "C:\Users\Student\Anaconda3\lib\site-packages\django\template\base.py", line 904, in render_annotated
    return self.render(context)
  File "C:\Users\Student\Anaconda3\lib\site-packages\django\template\defaulttags.py", line 443, in render
    url = reverse(view_name, args=args, kwargs=kwargs, current_app=current_app)
  File "C:\Users\Student\Anaconda3\lib\site-packages\django\urls\base.py", line 90, in reverse
    return iri_to_uri(resolver._reverse_with_prefix(view, prefix, *args, **kwargs))
  File "C:\Users\Student\Anaconda3\lib\site-packages\django\urls\resolvers.py", line 668, in _reverse_with_prefix
    raise NoReverseMatch(msg)
django.urls.exceptions.NoReverseMatch: Reverse for 'video_form' with keyword arguments '{'slug': ''}' not found. 1 pattern(s) tried: ['form_video/(?P<slug>[-\\w]+)/$']
"GET /hello/ HTTP/1.1" 500 228063
Internal Server Error: /form_video/
Traceback (most recent call last):
  File "C:\Users\Student\Anaconda3\lib\site-packages\django\core\handlers\exception.py", line 34, in inner
    response = get_response(request)
  File "C:\Users\Student\Anaconda3\lib\site-packages\django\core\handlers\base.py", line 115, in _get_response
    response = self.process_exception_by_middleware(e, request)
  File "C:\Users\Student\Anaconda3\lib\site-packages\django\core\handlers\base.py", line 113, in _get_response
    response = wrapped_callback(request, *callback_args, **callback_kwargs)
  File "D:\django\docker\python2.0\src\video\views.py", line 63, in video_form
    if form.save():
  File "D:\django\docker\python2.0\src\video\forms.py", line 31, in save
    print(self.cleaned_data)
AttributeError: 'VideoForm' object has no attribute 'cleaned_data'
"POST /form_video/ HTTP/1.1" 500 72225
Internal Server Error: /hello/
Traceback (most recent call last):
  File "C:\Users\Student\Anaconda3\lib\site-packages\django\core\handlers\exception.py", line 34, in inner
    response = get_response(request)
  File "C:\Users\Student\Anaconda3\lib\site-packages\django\core\handlers\base.py", line 115, in _get_response
    response = self.process_exception_by_middleware(e, request)
  File "C:\Users\Student\Anaconda3\lib\site-packages\django\core\handlers\base.py", line 113, in _get_response
    response = wrapped_callback(request, *callback_args, **callback_kwargs)
  File "C:\Users\Student\Anaconda3\lib\site-packages\django\views\decorators\csrf.py", line 54, in wrapped_view
    return view_func(*args, **kwargs)
  File "C:\Users\Student\Anaconda3\lib\site-packages\django\views\generic\base.py", line 71, in view
    return self.dispatch(request, *args, **kwargs)
  File "C:\Users\Student\Anaconda3\lib\site-packages\rest_framework\views.py", line 505, in dispatch
    response = self.handle_exception(exc)
  File "C:\Users\Student\Anaconda3\lib\site-packages\rest_framework\views.py", line 465, in handle_exception
    self.raise_uncaught_exception(exc)
  File "C:\Users\Student\Anaconda3\lib\site-packages\rest_framework\views.py", line 476, in raise_uncaught_exception
    raise exc
  File "C:\Users\Student\Anaconda3\lib\site-packages\rest_framework\views.py", line 502, in dispatch
    response = handler(request, *args, **kwargs)
  File "C:\Users\Student\Anaconda3\lib\site-packages\rest_framework\decorators.py", line 50, in handler
    return func(*args, **kwargs)
  File "D:\django\docker\python2.0\src\video\views.py", line 20, in hello
    response['NeEbstisVideo'] = NeEbstisVideo()
TypeError: NeEbstisVideo() missing 1 required positional argument: 'request'
"GET /hello/?title=NameLess&slug=problemy-s-soblyudeniem-pravil&description=erteeryrty&url=outube.com%2Fembed%2Fe5Oib9wkZHs HTTP/1.1" 500 106553
Internal Server Error: /hello/
Traceback (most recent call last):
  File "C:\Users\Student\Anaconda3\lib\site-packages\django\core\handlers\exception.py", line 34, in inner
    response = get_response(request)
  File "C:\Users\Student\Anaconda3\lib\site-packages\django\core\handlers\base.py", line 115, in _get_response
    response = self.process_exception_by_middleware(e, request)
  File "C:\Users\Student\Anaconda3\lib\site-packages\django\core\handlers\base.py", line 113, in _get_response
    response = wrapped_callback(request, *callback_args, **callback_kwargs)
  File "C:\Users\Student\Anaconda3\lib\site-packages\django\views\decorators\csrf.py", line 54, in wrapped_view
    return view_func(*args, **kwargs)
  File "C:\Users\Student\Anaconda3\lib\site-packages\django\views\generic\base.py", line 71, in view
    return self.dispatch(request, *args, **kwargs)
  File "C:\Users\Student\Anaconda3\lib\site-packages\rest_framework\views.py", line 505, in dispatch
    response = self.handle_exception(exc)
  File "C:\Users\Student\Anaconda3\lib\site-packages\rest_framework\views.py", line 465, in handle_exception
    self.raise_uncaught_exception(exc)
  File "C:\Users\Student\Anaconda3\lib\site-packages\rest_framework\views.py", line 476, in raise_uncaught_exception
    raise exc
  File "C:\Users\Student\Anaconda3\lib\site-packages\rest_framework\views.py", line 502, in dispatch
    response = handler(request, *args, **kwargs)
  File "C:\Users\Student\Anaconda3\lib\site-packages\rest_framework\decorators.py", line 50, in handler
    return func(*args, **kwargs)
  File "D:\django\docker\python2.0\src\video\views.py", line 20, in hello
    response['NeEbstisVideo'] = NeEbstisVideo(request)
  File "D:\django\docker\python2.0\src\video\views.py", line 69, in NeEbstisVideo
    form = NeEbstisVideo(request.POST)
  File "D:\django\docker\python2.0\src\video\views.py", line 69, in NeEbstisVideo
    form = NeEbstisVideo(request.POST)
AttributeError: 'QueryDict' object has no attribute 'POST'
"GET /hello/?title=NameLess&slug=problemy-s-soblyudeniem-pravil&description=erteeryrty&url=outube.com%2Fembed%2Fe5Oib9wkZHs HTTP/1.1" 500 113097
Internal Server Error: /hello/
Traceback (most recent call last):
  File "C:\Users\Student\Anaconda3\lib\site-packages\django\core\handlers\exception.py", line 34, in inner
    response = get_response(request)
  File "C:\Users\Student\Anaconda3\lib\site-packages\django\core\handlers\base.py", line 115, in _get_response
    response = self.process_exception_by_middleware(e, request)
  File "C:\Users\Student\Anaconda3\lib\site-packages\django\core\handlers\base.py", line 113, in _get_response
    response = wrapped_callback(request, *callback_args, **callback_kwargs)
  File "C:\Users\Student\Anaconda3\lib\site-packages\django\views\decorators\csrf.py", line 54, in wrapped_view
    return view_func(*args, **kwargs)
  File "C:\Users\Student\Anaconda3\lib\site-packages\django\views\generic\base.py", line 71, in view
    return self.dispatch(request, *args, **kwargs)
  File "C:\Users\Student\Anaconda3\lib\site-packages\rest_framework\views.py", line 505, in dispatch
    response = self.handle_exception(exc)
  File "C:\Users\Student\Anaconda3\lib\site-packages\rest_framework\views.py", line 465, in handle_exception
    self.raise_uncaught_exception(exc)
  File "C:\Users\Student\Anaconda3\lib\site-packages\rest_framework\views.py", line 476, in raise_uncaught_exception
    raise exc
  File "C:\Users\Student\Anaconda3\lib\site-packages\rest_framework\views.py", line 502, in dispatch
    response = handler(request, *args, **kwargs)
  File "C:\Users\Student\Anaconda3\lib\site-packages\rest_framework\decorators.py", line 50, in handler
    return func(*args, **kwargs)
  File "D:\django\docker\python2.0\src\video\views.py", line 20, in hello
    response['NeEbstisVideo'] = NeEbstisVideo(request)
  File "D:\django\docker\python2.0\src\video\views.py", line 69, in NeEbstisVideo
    form = NeEbstisVideo(request.POST)
  File "D:\django\docker\python2.0\src\video\views.py", line 69, in NeEbstisVideo
    form = NeEbstisVideo(request.POST)
AttributeError: 'QueryDict' object has no attribute 'POST'
"GET /hello/ HTTP/1.1" 500 111092
Internal Server Error: /hello/
Traceback (most recent call last):
  File "C:\Users\Student\Anaconda3\lib\site-packages\django\core\handlers\exception.py", line 34, in inner
    response = get_response(request)
  File "C:\Users\Student\Anaconda3\lib\site-packages\django\core\handlers\base.py", line 115, in _get_response
    response = self.process_exception_by_middleware(e, request)
  File "C:\Users\Student\Anaconda3\lib\site-packages\django\core\handlers\base.py", line 113, in _get_response
    response = wrapped_callback(request, *callback_args, **callback_kwargs)
  File "C:\Users\Student\Anaconda3\lib\site-packages\django\views\decorators\csrf.py", line 54, in wrapped_view
    return view_func(*args, **kwargs)
  File "C:\Users\Student\Anaconda3\lib\site-packages\django\views\generic\base.py", line 71, in view
    return self.dispatch(request, *args, **kwargs)
  File "C:\Users\Student\Anaconda3\lib\site-packages\rest_framework\views.py", line 505, in dispatch
    response = self.handle_exception(exc)
  File "C:\Users\Student\Anaconda3\lib\site-packages\rest_framework\views.py", line 465, in handle_exception
    self.raise_uncaught_exception(exc)
  File "C:\Users\Student\Anaconda3\lib\site-packages\rest_framework\views.py", line 476, in raise_uncaught_exception
    raise exc
  File "C:\Users\Student\Anaconda3\lib\site-packages\rest_framework\views.py", line 502, in dispatch
    response = handler(request, *args, **kwargs)
  File "C:\Users\Student\Anaconda3\lib\site-packages\rest_framework\decorators.py", line 50, in handler
    return func(*args, **kwargs)
  File "D:\django\docker\python2.0\src\video\views.py", line 20, in hello
    response['NeEbstisVideo'] = NeEbstisVideo(request)
  File "D:\django\docker\python2.0\src\video\views.py", line 69, in NeEbstisVideo
    form = NeEbstisVideo(request.POST)
  File "D:\django\docker\python2.0\src\video\views.py", line 69, in NeEbstisVideo
    form = NeEbstisVideo(request.POST)
AttributeError: 'QueryDict' object has no attribute 'POST'
"GET /hello/ HTTP/1.1" 500 111227
Internal Server Error: /hello/
Traceback (most recent call last):
  File "C:\Users\Student\Anaconda3\lib\site-packages\django\core\handlers\exception.py", line 34, in inner
    response = get_response(request)
  File "C:\Users\Student\Anaconda3\lib\site-packages\django\core\handlers\base.py", line 115, in _get_response
    response = self.process_exception_by_middleware(e, request)
  File "C:\Users\Student\Anaconda3\lib\site-packages\django\core\handlers\base.py", line 113, in _get_response
    response = wrapped_callback(request, *callback_args, **callback_kwargs)
  File "C:\Users\Student\Anaconda3\lib\site-packages\django\views\decorators\csrf.py", line 54, in wrapped_view
    return view_func(*args, **kwargs)
  File "C:\Users\Student\Anaconda3\lib\site-packages\django\views\generic\base.py", line 71, in view
    return self.dispatch(request, *args, **kwargs)
  File "C:\Users\Student\Anaconda3\lib\site-packages\rest_framework\views.py", line 505, in dispatch
    response = self.handle_exception(exc)
  File "C:\Users\Student\Anaconda3\lib\site-packages\rest_framework\views.py", line 465, in handle_exception
    self.raise_uncaught_exception(exc)
  File "C:\Users\Student\Anaconda3\lib\site-packages\rest_framework\views.py", line 476, in raise_uncaught_exception
    raise exc
  File "C:\Users\Student\Anaconda3\lib\site-packages\rest_framework\views.py", line 502, in dispatch
    response = handler(request, *args, **kwargs)
  File "C:\Users\Student\Anaconda3\lib\site-packages\rest_framework\decorators.py", line 50, in handler
    return func(*args, **kwargs)
  File "D:\django\docker\python2.0\src\video\views.py", line 20, in hello
    response['NeEbstisVideo'] = NeEbstisVideo(request)
  File "D:\django\docker\python2.0\src\video\views.py", line 69, in NeEbstisVideo
    form = NeEbstisVideo(request.POST)
  File "D:\django\docker\python2.0\src\video\views.py", line 69, in NeEbstisVideo
    form = NeEbstisVideo(request.POST)
AttributeError: 'QueryDict' object has no attribute 'POST'
"GET /hello/ HTTP/1.1" 500 111227
Internal Server Error: /hello/
Traceback (most recent call last):
  File "C:\Users\Student\Anaconda3\lib\site-packages\django\core\handlers\exception.py", line 34, in inner
    response = get_response(request)
  File "C:\Users\Student\Anaconda3\lib\site-packages\django\core\handlers\base.py", line 115, in _get_response
    response = self.process_exception_by_middleware(e, request)
  File "C:\Users\Student\Anaconda3\lib\site-packages\django\core\handlers\base.py", line 113, in _get_response
    response = wrapped_callback(request, *callback_args, **callback_kwargs)
  File "C:\Users\Student\Anaconda3\lib\site-packages\django\views\decorators\csrf.py", line 54, in wrapped_view
    return view_func(*args, **kwargs)
  File "C:\Users\Student\Anaconda3\lib\site-packages\django\views\generic\base.py", line 71, in view
    return self.dispatch(request, *args, **kwargs)
  File "C:\Users\Student\Anaconda3\lib\site-packages\rest_framework\views.py", line 505, in dispatch
    response = self.handle_exception(exc)
  File "C:\Users\Student\Anaconda3\lib\site-packages\rest_framework\views.py", line 465, in handle_exception
    self.raise_uncaught_exception(exc)
  File "C:\Users\Student\Anaconda3\lib\site-packages\rest_framework\views.py", line 476, in raise_uncaught_exception
    raise exc
  File "C:\Users\Student\Anaconda3\lib\site-packages\rest_framework\views.py", line 502, in dispatch
    response = handler(request, *args, **kwargs)
  File "C:\Users\Student\Anaconda3\lib\site-packages\rest_framework\decorators.py", line 50, in handler
    return func(*args, **kwargs)
  File "D:\django\docker\python2.0\src\video\views.py", line 20, in hello
    response['NeEbstisVideo'] = NeEbstisVideo()
TypeError: NeEbstisVideo() missing 1 required positional argument: 'request'
"GET /hello/ HTTP/1.1" 500 104683
Internal Server Error: /hello/
Traceback (most recent call last):
  File "C:\Users\Student\Anaconda3\lib\site-packages\django\core\handlers\exception.py", line 34, in inner
    response = get_response(request)
  File "C:\Users\Student\Anaconda3\lib\site-packages\django\core\handlers\base.py", line 115, in _get_response
    response = self.process_exception_by_middleware(e, request)
  File "C:\Users\Student\Anaconda3\lib\site-packages\django\core\handlers\base.py", line 113, in _get_response
    response = wrapped_callback(request, *callback_args, **callback_kwargs)
  File "C:\Users\Student\Anaconda3\lib\site-packages\django\views\decorators\csrf.py", line 54, in wrapped_view
    return view_func(*args, **kwargs)
  File "C:\Users\Student\Anaconda3\lib\site-packages\django\views\generic\base.py", line 71, in view
    return self.dispatch(request, *args, **kwargs)
  File "C:\Users\Student\Anaconda3\lib\site-packages\rest_framework\views.py", line 505, in dispatch
    response = self.handle_exception(exc)
  File "C:\Users\Student\Anaconda3\lib\site-packages\rest_framework\views.py", line 465, in handle_exception
    self.raise_uncaught_exception(exc)
  File "C:\Users\Student\Anaconda3\lib\site-packages\rest_framework\views.py", line 476, in raise_uncaught_exception
    raise exc
  File "C:\Users\Student\Anaconda3\lib\site-packages\rest_framework\views.py", line 502, in dispatch
    response = handler(request, *args, **kwargs)
  File "C:\Users\Student\Anaconda3\lib\site-packages\rest_framework\decorators.py", line 50, in handler
    return func(*args, **kwargs)
  File "D:\django\docker\python2.0\src\video\views.py", line 20, in hello
    response['NeEbstisVideo'] = NeEbstisVideo()
TypeError: NeEbstisVideo() missing 1 required positional argument: 'request'
"GET /hello/ HTTP/1.1" 500 104689
Internal Server Error: /hello/
Traceback (most recent call last):
  File "C:\Users\Student\Anaconda3\lib\site-packages\django\core\handlers\exception.py", line 34, in inner
    response = get_response(request)
  File "C:\Users\Student\Anaconda3\lib\site-packages\django\core\handlers\base.py", line 115, in _get_response
    response = self.process_exception_by_middleware(e, request)
  File "C:\Users\Student\Anaconda3\lib\site-packages\django\core\handlers\base.py", line 113, in _get_response
    response = wrapped_callback(request, *callback_args, **callback_kwargs)
  File "C:\Users\Student\Anaconda3\lib\site-packages\django\views\decorators\csrf.py", line 54, in wrapped_view
    return view_func(*args, **kwargs)
  File "C:\Users\Student\Anaconda3\lib\site-packages\django\views\generic\base.py", line 71, in view
    return self.dispatch(request, *args, **kwargs)
  File "C:\Users\Student\Anaconda3\lib\site-packages\rest_framework\views.py", line 505, in dispatch
    response = self.handle_exception(exc)
  File "C:\Users\Student\Anaconda3\lib\site-packages\rest_framework\views.py", line 465, in handle_exception
    self.raise_uncaught_exception(exc)
  File "C:\Users\Student\Anaconda3\lib\site-packages\rest_framework\views.py", line 476, in raise_uncaught_exception
    raise exc
  File "C:\Users\Student\Anaconda3\lib\site-packages\rest_framework\views.py", line 502, in dispatch
    response = handler(request, *args, **kwargs)
  File "C:\Users\Student\Anaconda3\lib\site-packages\rest_framework\decorators.py", line 50, in handler
    return func(*args, **kwargs)
  File "D:\django\docker\python2.0\src\video\views.py", line 20, in hello
    response['NeEbstisVideo'] = NeEbstisVideo(request)
  File "D:\django\docker\python2.0\src\video\views.py", line 69, in NeEbstisVideo
    form = NeEbstisVideo(request.POST)
  File "D:\django\docker\python2.0\src\video\views.py", line 69, in NeEbstisVideo
    form = NeEbstisVideo(request.POST)
AttributeError: 'QueryDict' object has no attribute 'POST'
"GET /hello/ HTTP/1.1" 500 111233
Internal Server Error: /hello/
Traceback (most recent call last):
  File "C:\Users\Student\Anaconda3\lib\site-packages\django\core\handlers\exception.py", line 34, in inner
    response = get_response(request)
  File "C:\Users\Student\Anaconda3\lib\site-packages\django\core\handlers\base.py", line 115, in _get_response
    response = self.process_exception_by_middleware(e, request)
  File "C:\Users\Student\Anaconda3\lib\site-packages\django\core\handlers\base.py", line 113, in _get_response
    response = wrapped_callback(request, *callback_args, **callback_kwargs)
  File "C:\Users\Student\Anaconda3\lib\site-packages\django\views\decorators\csrf.py", line 54, in wrapped_view
    return view_func(*args, **kwargs)
  File "C:\Users\Student\Anaconda3\lib\site-packages\django\views\generic\base.py", line 71, in view
    return self.dispatch(request, *args, **kwargs)
  File "C:\Users\Student\Anaconda3\lib\site-packages\rest_framework\views.py", line 505, in dispatch
    response = self.handle_exception(exc)
  File "C:\Users\Student\Anaconda3\lib\site-packages\rest_framework\views.py", line 465, in handle_exception
    self.raise_uncaught_exception(exc)
  File "C:\Users\Student\Anaconda3\lib\site-packages\rest_framework\views.py", line 476, in raise_uncaught_exception
    raise exc
  File "C:\Users\Student\Anaconda3\lib\site-packages\rest_framework\views.py", line 502, in dispatch
    response = handler(request, *args, **kwargs)
  File "C:\Users\Student\Anaconda3\lib\site-packages\rest_framework\decorators.py", line 50, in handler
    return func(*args, **kwargs)
  File "D:\django\docker\python2.0\src\video\views.py", line 20, in hello
    response['NeEbstisVideo'] = NeEbstisVideo(request)
  File "D:\django\docker\python2.0\src\video\views.py", line 69, in NeEbstisVideo
    form = NeEbstisVideo(request.POST)
  File "D:\django\docker\python2.0\src\video\views.py", line 69, in NeEbstisVideo
    form = NeEbstisVideo(request.POST)
AttributeError: 'QueryDict' object has no attribute 'POST'
"GET /hello/ HTTP/1.1" 500 111233
Internal Server Error: /hello/
Traceback (most recent call last):
  File "C:\Users\Student\Anaconda3\lib\site-packages\django\core\handlers\exception.py", line 34, in inner
    response = get_response(request)
  File "C:\Users\Student\Anaconda3\lib\site-packages\django\core\handlers\base.py", line 115, in _get_response
    response = self.process_exception_by_middleware(e, request)
  File "C:\Users\Student\Anaconda3\lib\site-packages\django\core\handlers\base.py", line 113, in _get_response
    response = wrapped_callback(request, *callback_args, **callback_kwargs)
  File "C:\Users\Student\Anaconda3\lib\site-packages\django\views\decorators\csrf.py", line 54, in wrapped_view
    return view_func(*args, **kwargs)
  File "C:\Users\Student\Anaconda3\lib\site-packages\django\views\generic\base.py", line 71, in view
    return self.dispatch(request, *args, **kwargs)
  File "C:\Users\Student\Anaconda3\lib\site-packages\rest_framework\views.py", line 505, in dispatch
    response = self.handle_exception(exc)
  File "C:\Users\Student\Anaconda3\lib\site-packages\rest_framework\views.py", line 465, in handle_exception
    self.raise_uncaught_exception(exc)
  File "C:\Users\Student\Anaconda3\lib\site-packages\rest_framework\views.py", line 476, in raise_uncaught_exception
    raise exc
  File "C:\Users\Student\Anaconda3\lib\site-packages\rest_framework\views.py", line 502, in dispatch
    response = handler(request, *args, **kwargs)
  File "C:\Users\Student\Anaconda3\lib\site-packages\rest_framework\decorators.py", line 50, in handler
    return func(*args, **kwargs)
  File "D:\django\docker\python2.0\src\video\views.py", line 20, in hello
    response['NeEbstisVideo'] = NeEbstisVideo(request)
  File "D:\django\docker\python2.0\src\video\views.py", line 69, in NeEbstisVideo
    form = NeEbstisVideo(request.POST)
  File "D:\django\docker\python2.0\src\video\views.py", line 69, in NeEbstisVideo
    form = NeEbstisVideo(request.POST)
AttributeError: 'QueryDict' object has no attribute 'POST'
"GET /hello/ HTTP/1.1" 500 111233
Internal Server Error: /hello/
Traceback (most recent call last):
  File "C:\Users\Student\Anaconda3\lib\site-packages\rest_framework\request.py", line 409, in __getattr__
    return getattr(self._request, attr)
AttributeError: 'WSGIRequest' object has no attribute 'get'

During handling of the above exception, another exception occurred:

Traceback (most recent call last):
  File "C:\Users\Student\Anaconda3\lib\site-packages\django\core\handlers\exception.py", line 34, in inner
    response = get_response(request)
  File "C:\Users\Student\Anaconda3\lib\site-packages\django\core\handlers\base.py", line 115, in _get_response
    response = self.process_exception_by_middleware(e, request)
  File "C:\Users\Student\Anaconda3\lib\site-packages\django\core\handlers\base.py", line 113, in _get_response
    response = wrapped_callback(request, *callback_args, **callback_kwargs)
  File "C:\Users\Student\Anaconda3\lib\site-packages\django\views\decorators\csrf.py", line 54, in wrapped_view
    return view_func(*args, **kwargs)
  File "C:\Users\Student\Anaconda3\lib\site-packages\django\views\generic\base.py", line 71, in view
    return self.dispatch(request, *args, **kwargs)
  File "C:\Users\Student\Anaconda3\lib\site-packages\rest_framework\views.py", line 505, in dispatch
    response = self.handle_exception(exc)
  File "C:\Users\Student\Anaconda3\lib\site-packages\rest_framework\views.py", line 465, in handle_exception
    self.raise_uncaught_exception(exc)
  File "C:\Users\Student\Anaconda3\lib\site-packages\rest_framework\views.py", line 476, in raise_uncaught_exception
    raise exc
  File "C:\Users\Student\Anaconda3\lib\site-packages\rest_framework\views.py", line 502, in dispatch
    response = handler(request, *args, **kwargs)
  File "C:\Users\Student\Anaconda3\lib\site-packages\rest_framework\decorators.py", line 50, in handler
    return func(*args, **kwargs)
  File "D:\django\docker\python2.0\src\video\views.py", line 21, in hello
    return render(request, "all_video.html", response)
  File "C:\Users\Student\Anaconda3\lib\site-packages\django\shortcuts.py", line 36, in render
    content = loader.render_to_string(template_name, context, request, using=using)
  File "C:\Users\Student\Anaconda3\lib\site-packages\django\template\loader.py", line 62, in render_to_string
    return template.render(context, request)
  File "C:\Users\Student\Anaconda3\lib\site-packages\django\template\backends\django.py", line 61, in render
    return self.template.render(context)
  File "C:\Users\Student\Anaconda3\lib\site-packages\django\template\base.py", line 171, in render
    return self._render(context)
  File "C:\Users\Student\Anaconda3\lib\site-packages\django\template\base.py", line 163, in _render
    return self.nodelist.render(context)
  File "C:\Users\Student\Anaconda3\lib\site-packages\django\template\base.py", line 937, in render
    bit = node.render_annotated(context)
  File "C:\Users\Student\Anaconda3\lib\site-packages\django\template\base.py", line 904, in render_annotated
    return self.render(context)
  File "C:\Users\Student\Anaconda3\lib\site-packages\django\template\loader_tags.py", line 150, in render
    return compiled_parent._render(context)
  File "C:\Users\Student\Anaconda3\lib\site-packages\django\template\base.py", line 163, in _render
    return self.nodelist.render(context)
  File "C:\Users\Student\Anaconda3\lib\site-packages\django\template\base.py", line 937, in render
    bit = node.render_annotated(context)
  File "C:\Users\Student\Anaconda3\lib\site-packages\django\template\base.py", line 904, in render_annotated
    return self.render(context)
  File "C:\Users\Student\Anaconda3\lib\site-packages\django\template\loader_tags.py", line 62, in render
    result = block.nodelist.render(context)
  File "C:\Users\Student\Anaconda3\lib\site-packages\django\template\base.py", line 937, in render
    bit = node.render_annotated(context)
  File "C:\Users\Student\Anaconda3\lib\site-packages\django\template\base.py", line 904, in render_annotated
    return self.render(context)
  File "C:\Users\Student\Anaconda3\lib\site-packages\django\template\base.py", line 993, in render
    return render_value_in_context(output, context)
  File "C:\Users\Student\Anaconda3\lib\site-packages\django\template\base.py", line 972, in render_value_in_context
    value = str(value)
  File "C:\Users\Student\Anaconda3\lib\site-packages\django\utils\html.py", line 388, in <lambda>
    klass.__str__ = lambda self: mark_safe(klass_str(self))
  File "C:\Users\Student\Anaconda3\lib\site-packages\django\forms\forms.py", line 142, in __str__
    return self.as_table()
  File "C:\Users\Student\Anaconda3\lib\site-packages\django\forms\forms.py", line 284, in as_table
    errors_on_separate_row=False,
  File "C:\Users\Student\Anaconda3\lib\site-packages\django\forms\forms.py", line 202, in _html_output
    top_errors = self.non_field_errors()  # Errors that should be displayed above all fields.
  File "C:\Users\Student\Anaconda3\lib\site-packages\django\forms\forms.py", line 313, in non_field_errors
    return self.errors.get(NON_FIELD_ERRORS, self.error_class(error_class='nonfield'))
  File "C:\Users\Student\Anaconda3\lib\site-packages\django\forms\forms.py", line 180, in errors
    self.full_clean()
  File "C:\Users\Student\Anaconda3\lib\site-packages\django\forms\forms.py", line 381, in full_clean
    self._clean_fields()
  File "C:\Users\Student\Anaconda3\lib\site-packages\django\forms\forms.py", line 393, in _clean_fields
    value = field.widget.value_from_datadict(self.data, self.files, self.add_prefix(name))
  File "C:\Users\Student\Anaconda3\lib\site-packages\django\forms\widgets.py", line 258, in value_from_datadict
    return data.get(name)
  File "C:\Users\Student\Anaconda3\lib\site-packages\rest_framework\request.py", line 411, in __getattr__
    return self.__getattribute__(attr)
AttributeError: 'Request' object has no attribute 'get'
"GET /hello/ HTTP/1.1" 500 273108
Internal Server Error: /hello/
Traceback (most recent call last):
  File "C:\Users\Student\Anaconda3\lib\site-packages\rest_framework\request.py", line 409, in __getattr__
    return getattr(self._request, attr)
AttributeError: 'WSGIRequest' object has no attribute 'get'

During handling of the above exception, another exception occurred:

Traceback (most recent call last):
  File "C:\Users\Student\Anaconda3\lib\site-packages\django\core\handlers\exception.py", line 34, in inner
    response = get_response(request)
  File "C:\Users\Student\Anaconda3\lib\site-packages\django\core\handlers\base.py", line 115, in _get_response
    response = self.process_exception_by_middleware(e, request)
  File "C:\Users\Student\Anaconda3\lib\site-packages\django\core\handlers\base.py", line 113, in _get_response
    response = wrapped_callback(request, *callback_args, **callback_kwargs)
  File "C:\Users\Student\Anaconda3\lib\site-packages\django\views\decorators\csrf.py", line 54, in wrapped_view
    return view_func(*args, **kwargs)
  File "C:\Users\Student\Anaconda3\lib\site-packages\django\views\generic\base.py", line 71, in view
    return self.dispatch(request, *args, **kwargs)
  File "C:\Users\Student\Anaconda3\lib\site-packages\rest_framework\views.py", line 505, in dispatch
    response = self.handle_exception(exc)
  File "C:\Users\Student\Anaconda3\lib\site-packages\rest_framework\views.py", line 465, in handle_exception
    self.raise_uncaught_exception(exc)
  File "C:\Users\Student\Anaconda3\lib\site-packages\rest_framework\views.py", line 476, in raise_uncaught_exception
    raise exc
  File "C:\Users\Student\Anaconda3\lib\site-packages\rest_framework\views.py", line 502, in dispatch
    response = handler(request, *args, **kwargs)
  File "C:\Users\Student\Anaconda3\lib\site-packages\rest_framework\decorators.py", line 50, in handler
    return func(*args, **kwargs)
  File "D:\django\docker\python2.0\src\video\views.py", line 21, in hello
    return render(request, "all_video.html", response)
  File "C:\Users\Student\Anaconda3\lib\site-packages\django\shortcuts.py", line 36, in render
    content = loader.render_to_string(template_name, context, request, using=using)
  File "C:\Users\Student\Anaconda3\lib\site-packages\django\template\loader.py", line 62, in render_to_string
    return template.render(context, request)
  File "C:\Users\Student\Anaconda3\lib\site-packages\django\template\backends\django.py", line 61, in render
    return self.template.render(context)
  File "C:\Users\Student\Anaconda3\lib\site-packages\django\template\base.py", line 171, in render
    return self._render(context)
  File "C:\Users\Student\Anaconda3\lib\site-packages\django\template\base.py", line 163, in _render
    return self.nodelist.render(context)
  File "C:\Users\Student\Anaconda3\lib\site-packages\django\template\base.py", line 937, in render
    bit = node.render_annotated(context)
  File "C:\Users\Student\Anaconda3\lib\site-packages\django\template\base.py", line 904, in render_annotated
    return self.render(context)
  File "C:\Users\Student\Anaconda3\lib\site-packages\django\template\loader_tags.py", line 150, in render
    return compiled_parent._render(context)
  File "C:\Users\Student\Anaconda3\lib\site-packages\django\template\base.py", line 163, in _render
    return self.nodelist.render(context)
  File "C:\Users\Student\Anaconda3\lib\site-packages\django\template\base.py", line 937, in render
    bit = node.render_annotated(context)
  File "C:\Users\Student\Anaconda3\lib\site-packages\django\template\base.py", line 904, in render_annotated
    return self.render(context)
  File "C:\Users\Student\Anaconda3\lib\site-packages\django\template\loader_tags.py", line 62, in render
    result = block.nodelist.render(context)
  File "C:\Users\Student\Anaconda3\lib\site-packages\django\template\base.py", line 937, in render
    bit = node.render_annotated(context)
  File "C:\Users\Student\Anaconda3\lib\site-packages\django\template\base.py", line 904, in render_annotated
    return self.render(context)
  File "C:\Users\Student\Anaconda3\lib\site-packages\django\template\base.py", line 993, in render
    return render_value_in_context(output, context)
  File "C:\Users\Student\Anaconda3\lib\site-packages\django\template\base.py", line 972, in render_value_in_context
    value = str(value)
  File "C:\Users\Student\Anaconda3\lib\site-packages\django\utils\html.py", line 388, in <lambda>
    klass.__str__ = lambda self: mark_safe(klass_str(self))
  File "C:\Users\Student\Anaconda3\lib\site-packages\django\forms\forms.py", line 142, in __str__
    return self.as_table()
  File "C:\Users\Student\Anaconda3\lib\site-packages\django\forms\forms.py", line 284, in as_table
    errors_on_separate_row=False,
  File "C:\Users\Student\Anaconda3\lib\site-packages\django\forms\forms.py", line 202, in _html_output
    top_errors = self.non_field_errors()  # Errors that should be displayed above all fields.
  File "C:\Users\Student\Anaconda3\lib\site-packages\django\forms\forms.py", line 313, in non_field_errors
    return self.errors.get(NON_FIELD_ERRORS, self.error_class(error_class='nonfield'))
  File "C:\Users\Student\Anaconda3\lib\site-packages\django\forms\forms.py", line 180, in errors
    self.full_clean()
  File "C:\Users\Student\Anaconda3\lib\site-packages\django\forms\forms.py", line 381, in full_clean
    self._clean_fields()
  File "C:\Users\Student\Anaconda3\lib\site-packages\django\forms\forms.py", line 393, in _clean_fields
    value = field.widget.value_from_datadict(self.data, self.files, self.add_prefix(name))
  File "C:\Users\Student\Anaconda3\lib\site-packages\django\forms\widgets.py", line 258, in value_from_datadict
    return data.get(name)
  File "C:\Users\Student\Anaconda3\lib\site-packages\rest_framework\request.py", line 411, in __getattr__
    return self.__getattribute__(attr)
AttributeError: 'Request' object has no attribute 'get'
"GET /hello/ HTTP/1.1" 500 273108
Not Found: /hello/{url 'NeEbstisVideo' }
"POST /hello/%7Burl%20'NeEbstisVideo'%20%7D HTTP/1.1" 404 3196
Not Found: /hello/{url 'NeEbstisVideo' }
"POST /hello/%7Burl%20'NeEbstisVideo'%20%7D HTTP/1.1" 404 3196
